Workbook

Sheet INSTRUCTIONS
B2: Section | C2: Instruction
B3: General Use | C3: Do not rename, move, or delete any existing tabs.
C4: Only input data in cells that have blue text.
C5: Use drop-downs where provided to ensure consistent data entry.
C6: Update the file monthly as needed to keep dashboard data accurate.
B7: Blue Text Fields | C7: Blue text indicates a a cell for data to be entered.
B8: Editing Guidance | C8: Do not remove rows with formulas. Add new rows at the bottom of the tables.
B9: Data Format | C9: Use MM/DD/YYYY format for all dates. Ensure consistent spelling for trade names and status types. Date needs to be first of the month to pull data.
B10: Backup Reminder | C10: Save a backup of the file before major updates. Use version control in the file name if necessary.
B11: Dashboard Tab | C11: The dashboard is read-only. All charts and KPIs auto-populate from the other tabs. Do not manually enter data in this tab.
B12: Schedule Tab | C12: Enter Critical path items only! Include progress, upcoming look-ahead items, and any delays.
B13: Safety Tab | C13: Record toolbox talks, standdowns, incidents, weekend/OT work, and site visits (DOB, FDNY, OSHA).
B14: Risks Tab | C14: Use this tab to track key project risks, including scope gaps, outstanding decisions, coordination issues, or external dependencies. For each item, define the risk, assess its impact, outline the mitigation strategy, assign an owner, and update the status
B15: Quality Tab | C15: Log top issues by trade, open days, benchmark inspections, and NCRs. Include resolution strategy.
B16: RFIs & Submittals Tab | C16: Track RFIs and Submittals. Log RFI number, description, status, submission and response dates. Use "Open", "Closed", or "Overdue" for status tracking.
B17: Financials Tab | C17: Input actual costs, projected costs, and budget vs actuals. GC/GR variance tracking is automated.
B18: Scorecard Tab | C18: Use this tab to evaluate overall project health using a weighted scoring system across key performance indicators, including financials, schedule, safety, and reporting. Input each category's score based on defined metrics, and update regularly to monitor performance trends. Include client satisfaction survey results below to track feedback and engagement
B20: SECTION | C20: RESPONSIBILITY | D20: CONTRIBUTOR
B21: Dashboard | C21: Read Only. Ask Administrator
B22: Wins | C22: PM | D22: Superintendent & Foremen
B23: Schedule | C23: PM | D23: Superintendent & Foremen
B24: Risks | C24: PM | D24: Superintendent & Foremen
B25: Safety | C25: PM | D25: Superintendent & Foremen
B26: Quality | C26: PM | D26: Superintendent & Foremen
B27: Submittals & RFIs | C27: PM | D27: Superintendent & Foremen
B28: Financial | C28: QS/Estimator | D28: PM & Project Accountant
B29: Scorecard Calc | C29: PM & Marketing | D29: PM & Marketing

Sheet DASHBOARD
B2: Monthly Progress Report | AU2: #VALUE!
AU4: 45778
B7: WINS (REALIZED) | J7: SCHEDULE | AQ7: FINANCIAL
Q8: Approved by Client
C9: =IF(WINS!C3=0," ",WINS!C3) -> Topped Out Superstructure | M9: Start | O9: Finish | P9: MTM Delta | T9: Rev # | AR9: Original Contract Amt. | AT9: =FINANCIALS!C3 -> 8800000 | AU9: MTM DELTA
L10: Contract | M10: =SCHEDULE!D4 -> 45666 | O10: =SCHEDULE!E4 -> 46149 | P10: =+SCHEDULE!E22 -> 0 | V10: =+Table3714[[#Headers],[STATUS SUMMARY]] -> STATUS SUMMARY | W10: =+SCHEDULE!E34 -> CRITICAL DELAYS / VARIANCES | AB10: =+SCHEDULE!F34 -> RECOVERY PLAN | AG10: =+SCHEDULE!G34 -> FORECAST IMPACT | AL10: =+SCHEDULE!H34 -> NOTES / ACTION ITEMS | AR10: Current Contract Amt. | AT10: =FINANCIALS!C4 -> 9116960.5 | AU10: =FINANCIALS!E4 -> 0.011387166
L11: Baseline | M11: =SCHEDULE!F4 -> 45665 | O11: =+SCHEDULE!G14 -> 46198 | P11: =+SCHEDULE!G22 -> 0 | Q11: =+IF(SCHEDULE!G16=0," ",SCHEDULE!G16) -> 🔴 N | T11: =+IF(SCHEDULE!G17=0," ",SCHEDULE!G17) -> Rev#1 | AR11: Variance | AT11: =(AT10-AT9)/AT9 -> 0.036018236
L12: Currently Tracking | M12: =+SCHEDULE!H4 -> 45665 | O12: =+SCHEDULE!I4 -> 46198 | P12: =+SCHEDULE!I22 -> 0 | V12: =+SCHEDULE!D35 -> 🔴 At Risk | W12: =SCHEDULE!E35 -> [List specific issues: e.g., delayed delivery, inspections, manpower shortage] | AB12: =SCHEDULE!F35 -> [Explain steps being taken: e.g., OT, resequencing, adding crews] | AG12: =SCHEDULE!G35 -> [Impact to key milestones or turnover] | AL12: =SCHEDULE!H35 -> [Escalations, decisions needed, risks to monitor] | AR12: Pending CO's | AT12: =FINANCIALS!C5 -> 84328.46 | AU12: =FINANCIALS!E5 -> -0.64112953
AR13: Contingency Remaining | AT13: =FINANCIALS!C9 -> N/A
L14: Actual | M14: =SCHEDULE!J4 -> 45665 | O14: =IF(SCHEDULE!K14="NA","TBD",SCHEDULE!K14) -> TBD | P14: =+SCHEDULE!K22 -> TBD | V14: =+SCHEDULE!D36 -> 🔴 At Risk | W14: =SCHEDULE!E36 -> [List specific issues: e.g., delayed delivery, inspections, manpower shortage] | AB14: =SCHEDULE!F36 -> [Explain steps being taken: e.g., OT, resequencing, adding crews] | AG14: =SCHEDULE!G36 -> [Impact to key milestones or turnover] | AL14: =SCHEDULE!H36 -> [Escalations, decisions needed, risks to monitor] | AR14: Billed this Month | AT14: =TEXT(FINANCIALS!C11,"$#,##0.0") & " / " & TEXT(FINANCIALS!C11/FINANCIALS!C4,"0.0%") -> $400,000.0 / 4.4%
C15: =IF(WINS!C4=0," ",WINS!C4) -> Major Submittals Approved (Window Wall, Porcelain, Doors) | AR15: Total Billed | AT15: =TEXT(FINANCIALS!C10,"$#,##0.0") & " / " & TEXT(FINANCIALS!C10/FINANCIALS!C4,"0.0%") -> $2,997,804.2 / 32.9%
L16: =+IF((O12-O10)=0,"0 days",O12-O10) -> 49 | M16: =+IF((O12-O11)=0,"0 days",O12-O11) -> 0 days | O16: =IF(L16>0,"Warning, provide Recovery Plan","") -> Warning, provide Recovery Plan | V16: =SCHEDULE!D37 -> 🟡 Behind | W16: =SCHEDULE!E37 -> Delayed delivery | AB16: =SCHEDULE!F37 -> [Explain steps being taken: e.g., OT, resequencing, adding crews] | AG16: =SCHEDULE!G37 -> [Impact to key milestones or turnover] | AL16: =SCHEDULE!H37 -> [Escalations, decisions needed, risks to monitor] | AR16: Total Paid | AT16: =TEXT(FINANCIALS!C12,"$#,##0.0") & " / " & TEXT(FINANCIALS!C12/FINANCIALS!C4,"0.0%") -> $2,683,097.5 / 29.4%
L17: Contract | M17: Baseline | P17: AVG Daily Manpower | AR17: Remaining Balance | AT17: =TEXT(FINANCIALS!C13,"$#,##0.0") & " / " & TEXT(FINANCIALS!C13/FINANCIALS!C4,"0.0%") -> $6,433,863.0 / 70.6%
L18: COMPLETION VARIANCE | P18: =+SCHEDULE!C26 -> Sub 1 | T18: =+SCHEDULE!D26 -> 0 | V18: =+SCHEDULE!D38 -> 🔴 At Risk | W18: =SCHEDULE!E38 -> mapower | AB18: =SCHEDULE!F38 -> [Explain steps being taken: e.g., OT, resequencing, adding crews] | AG18: =SCHEDULE!G38 -> [Impact to key milestones or turnover] | AL18: =SCHEDULE!H38 -> [Escalations, decisions needed, risks to monitor] | AR18: Retainage | AT18: =TEXT(FINANCIALS!C14,"$#,##0.0") & " / " & TEXT(FINANCIALS!C14/FINANCIALS!C4,"0.0%") -> $127,441.6 / 1.4%
L19: =COUNTIF(Table5[START VARIANCE],">=1")/COUNT(Table5[ACTUAL START]) -> 0.4 | O19: =IF(L19>0.2,"Warning, provide Recovery Plan","") -> Warning, provide Recovery Plan | P19: =+SCHEDULE!C27 -> Sub 2 | T19: =+SCHEDULE!D27 -> 0 | AR19: Cost to Complete | AT19: =TEXT(FINANCIALS!C15,"$#,##0.0") & " / " & TEXT(FINANCIALS!C15/FINANCIALS!C4,"0.0%") -> $6,786,492.3 / 74.4%
L20: CRITICAL MISSED STARTS | P20: =+SCHEDULE!C28 -> Sub 3 | T20: =+SCHEDULE!D28 -> 0 | V20: =SCHEDULE!D39 -> 🟢 On Track | W20: =SCHEDULE!E39 -> manpower | AB20: =SCHEDULE!F39 -> [Explain steps being taken: e.g., OT, resequencing, adding crews] | AG20: =SCHEDULE!G39 -> [Impact to key milestones or turnover] | AL20: =SCHEDULE!H39 -> [Escalations, decisions needed, risks to monitor]
C21: =IF(WINS!C5=0," ",WINS!C5) -> No accidents | L21: =IF(M12>TODAY(),0,((TODAY()-M12))/(O12-M12)) -> 0.74859287 | O21: =IF(L21<((TODAY()-M11))/(O11-M11),"Warning, slippage, provide recovery plan","") | P21: =+SCHEDULE!C29 -> Sub 4 | T21: =+SCHEDULE!D29 -> 0 | AT21: =FINANCIALS!C6 -> 1
L22: PROJECT % COMPLETE | P22: =+SCHEDULE!C30 -> Sub 5 | T22: =+SCHEDULE!D30 -> 0 | AT22: AGE OF OLDEST UNAPPROVED CO
AT23: =FINANCIALS!D62 -> 0.95000001
AT24: RISK BOUGHT OUT
J25: RISKS (Ranked by Severity) | AT25: =+FINANCIALS!F57 -> 1
AT26: AGING BALANCE
C27: =IF(WINS!C6=0," ",WINS!C6) -> Quickly Rescinded PSWO | K27: =+RISKS!C2 -> RISK DESCRIPTION | T27: =+RISKS!D2 -> IMPACT | V27: =+RISKS!E2 -> MITIGATION STRATEGY | AJ27: =+RISKS!F2 -> OWNER | AM27: =+RISKS!G2 -> STATUS | AT27: =FINANCIALS!F56 -> 8.8181818
K28: =+RISKS!C3 -> Change Orders Outstanding Change Orders Outstanding Change Orders Outstanding | T28: =+RISKS!D3 -> 🟡 Medium | V28: =+RISKS!E3 -> Change Orders Outstanding Change Orders Outstanding Change Orders Outstanding Change Orders Outstanding Change Orders | AJ28: =+RISKS!F3 -> Dir. of Construction | AM28: =+RISKS!G3 -> 🟢 Complete | AT28: AVG. DAYS FOR PAYMENT RECEIVED
K30: =+RISKS!C4 -> Access Agreements with Neighbors | T30: =+RISKS!D4 -> 🟡 Medium | V30: =+RISKS!E4 -> Change Orders Outstanding Change Orders Outstanding Change Orders Outstanding Change Orders Outstanding Change Orders | AJ30: =+RISKS!F4 -> Dir. of Construction | AM30: =+RISKS!G4 -> 🟡 Planned | AS30: ="Profitability is " &FINANCIALS!C7 -> Profitability is Margin fade but no plan
AS31: =FINANCIALS!C8 -> < 50% = 🔴 Bad Cash Position
K32: =+RISKS!C5 -> Trades to award: | T32: =+RISKS!D5 -> 🟡 Medium | V32: =+RISKS!E5 -> Change Orders Outstanding Change Orders Outstanding Change Orders Outstanding Change Orders Outstanding Change Orders | AJ32: =+RISKS!F5 -> Dir. of Construction | AM32: =+RISKS!G5 -> 🟡 In Progress | AR32: =FINANCIALS!E65 -> 🟢 Y | AT32: MONTH END CLOSED OUT
AR33: =FINANCIALS!E66 -> 🔴 N | AT33: PROCORE FORECASTING IN LINE W/SCHEDULE
B34: FOCUS AREAS (UPCOMING MTH) | K34: =+RISKS!C6 -> Kitchen Cabinet Design | T34: =+RISKS!D6 -> 🟡 Medium | V34: =+RISKS!E6 -> Change Orders Outstanding Change Orders Outstanding Change Orders Outstanding Change Orders Outstanding Change Orders | AJ34: =+RISKS!F6 -> Dir. of Construction | AM34: =+RISKS!G6 -> 🟢 Complete | AR34: =FINANCIALS!E67 -> 🔴 N | AT34: MONITORED RESOURCES UPDATED
C36: =IF(WINS!C9=0," ",WINS!C9) -> Topped Out Superstructure | K36: =+RISKS!C7 -> Kitchen Cabinet Design | T36: =+RISKS!D7 -> 🟡 Medium | V36: =+RISKS!E7 -> Change Orders Outstanding Change Orders Outstanding Change Orders Outstanding Change Orders Outstanding Change Orders | AJ36: =+RISKS!F7 -> Dir. of Construction | AM36: =+RISKS!G7 -> 🔴 Not Started | AS36: Budget | AT36: Forecast | AU36: Spent to Date / % | AV36: Status
AR37: GR's | AS37: =FINANCIALS!C19 -> 299746.97 | AT37: =FINANCIALS!D19 -> 89149.77 | AU37: =TEXT(FINANCIALS!E19,"$#,##0.00") & " / " & TEXT(FINANCIALS!E19/FINANCIALS!C19,"0.0%") -> $15,000.00 / 5.0% | AV37: =FINANCIALS!F19 -> 🔴 Over Budget
K38: =+RISKS!C8 -> Kitchen Cabinet Design | T38: =+RISKS!D8 -> 🔴 High | V38: =+RISKS!E8 -> Change Orders Outstanding Change Orders Outstanding Change Orders Outstanding Change Orders Outstanding Change Orders | AJ38: =+RISKS!F8 -> Dir. of Construction | AM38: =+RISKS!G8 -> 🔴 Not Started | AR38: GC's | AS38: =FINANCIALS!C20 -> 850018.69 | AT38: =FINANCIALS!D20 -> 323265.39 | AU38: =TEXT(FINANCIALS!E20,"$#,##0.00") & " / " & TEXT(FINANCIALS!E20/FINANCIALS!C20,"0.0%") -> $20,000.00 / 2.4% | AV38: =FINANCIALS!F20 -> 🟢 On Track
K40: =+RISKS!C9 -> Kitchen Cabinet Design | T40: =+RISKS!D9 -> ⚪ Low | V40: =+RISKS!E9 -> Change Orders Outstanding Change Orders Outstanding Change Orders Outstanding Change Orders Outstanding Change Orders | AJ40: =+RISKS!F9 -> Dir. of Construction | AM40: =+RISKS!G9 -> 🔴 Not Started | AT40: =TEXT(INDEX(FINANCIALS!J25:J55,MATCH(AU4,FINANCIALS!I25:I55,0)),"#,###,###") & " / " & TEXT(((INDEX(FINANCIALS!J25:J55,MATCH(AU4,FINANCIALS!I25:I55,0))-INDEX(FINANCIALS!J25:J55,MATCH((EDATE(AU4,-1)),FINANCIALS!I25:I55,0)))/INDEX(FINANCIALS!J25:J55,MATCH((EDATE(AU4,-1)),FINANCIALS!I25:I55,0))),"0%") -> 44 / 107% | AU40: =FINANCIALS!J56 -> 112.5
AT41: This Period / MTM Delta | AU41: Total to Date
C42: =IF(WINS!C10=0," ",WINS!C10) -> Major Submittals Approved (Window Wall, Porcelain, Doors) | K42: =+RISKS!C10 -> Kitchen Cabinet Design | T42: =+RISKS!D10 -> 🟡 Medium | V42: =+RISKS!E10 -> Change Orders Outstanding Change Orders Outstanding Change Orders Outstanding Change Orders Outstanding Change Orders | AJ42: =+RISKS!F10 -> Dir. of Construction | AM42: =+RISKS!G10 -> 🔴 Not Started | AT42: OT HOURS
AQ44: CRITICAL SUBMITTALS & RFIS
J46: SAFETY
C48: =IF(WINS!C11=0," ",WINS!C11) -> No accidents | K48: =SAFETY!B36 -> TIMEFRAME | M48: =SAFETY!C36 -> CATEGORY | P48: =SAFETY!D36 -> DESCRIPTION/ACTIVITY | U48: =SAFETY!E36 -> STATUS | W48: =SAFETY!F36 -> NOTES/OUTCOME/ACTION | AE48: =SAFETY!G36 -> RESPONSIBLE | AI48: =TEXT(INDEX(SAFETY!D3:D33,MATCH(AU4,SAFETY!C3:C33,0)),"#,###,###") & " / " & TEXT((INDEX(SAFETY!D3:D33,MATCH(AU4,SAFETY!C3:C33,0))-INDEX(SAFETY!D3:D33,MATCH((EDATE(AU4,-1)),SAFETY!C3:C33,0)))/INDEX(SAFETY!D3:D33,MATCH((EDATE(AU4,-1)),SAFETY!C3:C33,0)),"0.0%") -> 4,635 / 9.7% | AM48: =SAFETY!D34 -> 114231
K49: =SAFETY!B37 -> Lookback | M49: =SAFETY!C37 -> Toolbox Talk – Scheduled | P49: =SAFETY!D37 -> Scaffold Overbuild | U49: =SAFETY!E37 -> 🟢 Completed | W49: =SAFETY!F37 -> Signed off, executed per plan | AE49: =SAFETY!G37 -> Asst. Super | AI49: This Period / MTM Delta | AM49: Total to Date
AI50: TOTAL HOURS WORKED
...

Sheet WINS
B1: WINS (REALIZED)
B2: WIN # | C2: DESCRIPTION (TEXT NEEDS TO FIT IN THE COLUM WIDTH AND HEIGHT)
B3: WIN 1 | C3: Topped Out Superstructure
B4: WIN 2 | C4: Major Submittals Approved (Window Wall, Porcelain, Doors)
B5: WIN 3 | C5: No accidents
B6: WIN 4 | C6: Quickly Rescinded PSWO
B7: FOCUS AREAS (UPCOMING MTH)
B8: WIN # | C8: DESCRIPTION (TEXT NEEDS TO FIT IN THE COLUM WIDTH AND HEIGHT)
B9: FA 1 | C9: Topped Out Superstructure
B10: FA 2 | C10: Major Submittals Approved (Window Wall, Porcelain, Doors)
B11: FA 3 | C11: No accidents
B12: FA 4 | C12: Quickly Rescinded PSWO

Sheet SCHEDULE
C3: TASK | D3: CONTRACT START | E3: CONTRACT FINISH | F3: BASELINE START | G3: BASELINE FINISH | H3: CURRENT START | I3: CURRENT FINISH | J3: ACTUAL START | K3: ACTUAL FINISH | L3: START VARIANCE | M3: FINISH VARIANCE | P3: INSTRUCTIONS FOR USE
C4: Project Milestones (Start & Finish) | D4: =+MIN(D5:D14) -> 45666 | E4: =+MAX(E5:E14) -> 46149 | F4: =+MIN(F5:F14) -> 45665 | G4: =+MAX(G5:G14) -> 46198 | H4: =+MIN(H5:H14) -> 45665 | I4: =+MAX(I5:I14) -> 46198 | J4: =+MIN(J5:J14) -> 45665 | K4: =+MAX(K5:K14) -> 45740 | P4: 1. FIRST ROW IS LOCKED 2. ALL BLANKS CELL SHOULD RECEIVE AN NA 3. THE LAST LINE ON THIS TABLE SHOULD NEVER BE DELETED AND SHOULD ALWAYS BE SUB COMPLETETION 4. NEVER HAVE ANY BLANK ROWS
C5: Critical Path Item 1 | D5: 45666 | E5: 45672 | F5: 45665 | G5: 45665 | H5: 45665 | I5: 45665 | J5: 45665 | K5: 45665 | L5: =IF(Table5[[#This Row],[ACTUAL START]]="NA","",Table5[[#This Row],[ACTUAL START]]-Table5[[#This Row],[BASELINE START]]) -> 0 | M5: =IF(Table5[[#This Row],[CURRENT FINISH]]="NA","",Table5[[#This Row],[CURRENT FINISH]]-Table5[[#This Row],[BASELINE FINISH]]) -> 0
C6: Critical Path Item 2 | D6: 45666 | E6: 45694 | F6: 45699 | G6: 45699 | H6: 45728 | I6: 45728 | J6: 45728 | K6: 45728 | L6: =IF(Table5[[#This Row],[ACTUAL START]]="NA","",Table5[[#This Row],[ACTUAL START]]-Table5[[#This Row],[BASELINE START]]) -> 29 | M6: =IF(Table5[[#This Row],[CURRENT FINISH]]="NA","",Table5[[#This Row],[CURRENT FINISH]]-Table5[[#This Row],[BASELINE FINISH]]) -> 29
C7: Critical Path Item 3 | D7: 45695 | E7: 45701 | F7: 45707 | G7: 45707 | H7: 45740 | I7: 45740 | J7: 45740 | K7: 45740 | L7: =IF(Table5[[#This Row],[ACTUAL START]]="NA","",Table5[[#This Row],[ACTUAL START]]-Table5[[#This Row],[BASELINE START]]) -> 33 | M7: =IF(Table5[[#This Row],[CURRENT FINISH]]="NA","",Table5[[#This Row],[CURRENT FINISH]]-Table5[[#This Row],[BASELINE FINISH]]) -> 33
C8: Critical Path Item 4 | D8: 45695 | E8: 45701 | F8: 45707 | G8: 45707 | H8: 45740 | I8: 45740 | J8: 45707 | K8: 45707 | L8: =IF(Table5[[#This Row],[ACTUAL START]]="NA","",Table5[[#This Row],[ACTUAL START]]-Table5[[#This Row],[BASELINE START]]) -> 0 | M8: =IF(Table5[[#This Row],[CURRENT FINISH]]="NA","",Table5[[#This Row],[CURRENT FINISH]]-Table5[[#This Row],[BASELINE FINISH]]) -> 33
C9: Critical Path Item 5 | D9: 45792 | E9: 45792 | F9: 45758 | G9: 45758 | H9: 45824 | I9: 45828 | J9: NA | K9: NA | L9: =IF(Table5[[#This Row],[ACTUAL START]]="NA","",Table5[[#This Row],[ACTUAL START]]-Table5[[#This Row],[BASELINE START]]) | M9: =IF(Table5[[#This Row],[CURRENT FINISH]]="NA","",Table5[[#This Row],[CURRENT FINISH]]-Table5[[#This Row],[BASELINE FINISH]]) -> 70
C10: Critical Path Item 6 | D10: NA | E10: NA | F10: 45860 | G10: 45860 | H10: 45919 | I10: 45919 | J10: NA | K10: NA | L10: =IF(Table5[[#This Row],[ACTUAL START]]="NA","",Table5[[#This Row],[ACTUAL START]]-Table5[[#This Row],[BASELINE START]]) | M10: =IF(Table5[[#This Row],[CURRENT FINISH]]="NA","",Table5[[#This Row],[CURRENT FINISH]]-Table5[[#This Row],[BASELINE FINISH]]) -> 59
C11: Critical Path Item 7 | D11: 45894 | E11: 45894 | F11: 45938 | G11: 45938 | H11: 46020 | I11: 46020 | J11: NA | K11: NA | L11: =IF(Table5[[#This Row],[ACTUAL START]]="NA","",Table5[[#This Row],[ACTUAL START]]-Table5[[#This Row],[BASELINE START]]) | M11: =IF(Table5[[#This Row],[CURRENT FINISH]]="NA","",Table5[[#This Row],[CURRENT FINISH]]-Table5[[#This Row],[BASELINE FINISH]]) -> 82
C12: Critical Path Item 8 | D12: 46156 | E12: 46149 | F12: 46154 | G12: 46154 | H12: 46020 | I12: 46020 | J12: NA | K12: NA | L12: =IF(Table5[[#This Row],[ACTUAL START]]="NA","",Table5[[#This Row],[ACTUAL START]]-Table5[[#This Row],[BASELINE START]]) | M12: =IF(Table5[[#This Row],[CURRENT FINISH]]="NA","",Table5[[#This Row],[CURRENT FINISH]]-Table5[[#This Row],[BASELINE FINISH]]) -> -134
C13: Critical Path Item 9 | D13: 46184 | E13: 46149 | F13: 46198 | G13: 46198 | H13: 46142 | I13: 46142 | J13: NA | K13: NA | L13: =IF(Table5[[#This Row],[ACTUAL START]]="NA","",Table5[[#This Row],[ACTUAL START]]-Table5[[#This Row],[BASELINE START]]) | M13: =IF(Table5[[#This Row],[CURRENT FINISH]]="NA","",Table5[[#This Row],[CURRENT FINISH]]-Table5[[#This Row],[BASELINE FINISH]]) -> -56
C14: Contractural Substaintial Completion [DO NOT DELETE THIS LINE] | D14: 45666 | E14: 46149 | F14: 45666 | G14: 46198 | H14: 45666 | I14: 46198 | J14: NA | K14: NA | L14: =IF(Table5[[#This Row],[ACTUAL START]]="NA","",Table5[[#This Row],[ACTUAL START]]-Table5[[#This Row],[BASELINE START]]) | M14: =IF(Table5[[#This Row],[CURRENT FINISH]]="NA","",Table5[[#This Row],[CURRENT FINISH]]-Table5[[#This Row],[BASELINE FINISH]]) -> 0
E16: Baseline Approved by Client | G16: 🔴 N
E17: Baseline Revision | G17: Rev#1
C20: This Month | E20: =+E14 -> 46149 | G20: =+G14 -> 46198 | I20: =+I14 -> 46198 | K20: =+K14 -> NA
C21: Previous Month (Paste Special values) | E21: 46149 | G21: 46198 | I21: 46198 | L21: *Manually Input last months values. If first month reporting enter same value as this month.
C22: MTM Change | E22: =+E20-E21 -> 0 | G22: =+G20-G21 -> 0 | I22: =+I20-I21 -> 0 | K22: =+IF(K20="NA","TBD",K20-K21) -> TBD
C24: AVERAGE Daily Manpower
C25: Company Name | D25: Avg Daily over past 30 days
C26: Sub 1 | D26: 0
C27: Sub 2 | D27: 0
C28: Sub 3 | D28: 0
C29: Sub 4 | D29: 0
C30: Sub 5 | D30: 0
C34: SCHEDULE ITEM | D34: STATUS SUMMARY | E34: CRITICAL DELAYS / VARIANCES | F34: RECOVERY PLAN | G34: FORECAST IMPACT | H34: NOTES / ACTION ITEMS
C35: PRIORITY ITEM 1 | D35: 🔴 At Risk | E35: [List specific issues: e.g., delayed delivery, inspections, manpower shortage] | F35: [Explain steps being taken: e.g., OT, resequencing, adding crews] | G35: [Impact to key milestones or turnover] | H35: [Escalations, decisions needed, risks to monitor]
C36: PRIORITY ITEM 2 | D36: 🔴 At Risk | E36: [List specific issues: e.g., delayed delivery, inspections, manpower shortage] | F36: [Explain steps being taken: e.g., OT, resequencing, adding crews] | G36: [Impact to key milestones or turnover] | H36: [Escalations, decisions needed, risks to monitor]
C37: PRIORITY ITEM 3 | D37: 🟡 Behind | E37: Delayed delivery | F37: [Explain steps being taken: e.g., OT, resequencing, adding crews] | G37: [Impact to key milestones or turnover] | H37: [Escalations, decisions needed, risks to monitor]
C38: PRIORITY ITEM 4 | D38: 🔴 At Risk | E38: mapower | F38: [Explain steps being taken: e.g., OT, resequencing, adding crews] | G38: [Impact to key milestones or turnover] | H38: [Escalations, decisions needed, risks to monitor]
C39: PRIORITY ITEM 5 | D39: 🟢 On Track | E39: manpower | F39: [Explain steps being taken: e.g., OT, resequencing, adding crews] | G39: [Impact to key milestones or turnover] | H39: [Escalations, decisions needed, risks to monitor]
C41: INSTRUCTIONS FOR USE
C42: Status Summary should be brief but clear (e.g., "Behind due to facade delay", "On track post weather recovery"). Recovery Plan is critical if you’re off track—list actionable steps, not just “monitoring.” Forecast Impact should tie directly to milestone changes or risk to turnover date.

Sheet RISKS
B2: RISK # | C2: RISK DESCRIPTION | D2: IMPACT | E2: MITIGATION STRATEGY | F2: OWNER | G2: STATUS
B3: RISK 1 | C3: Change Orders Outstanding Change Orders Outstanding Change Orders Outstanding | D3: 🟡 Medium | E3: Change Orders Outstanding Change Orders Outstanding Change Orders Outstanding Change Orders Outstanding Change Orders | F3: Dir. of Construction | G3: 🟢 Complete
B4: RISK 2 | C4: Access Agreements with Neighbors | D4: 🟡 Medium | E4: Change Orders Outstanding Change Orders Outstanding Change Orders Outstanding Change Orders Outstanding Change Orders | F4: Dir. of Construction | G4: 🟡 Planned
B5: RISK 3 | C5: Trades to award: | D5: 🟡 Medium | E5: Change Orders Outstanding Change Orders Outstanding Change Orders Outstanding Change Orders Outstanding Change Orders | F5: Dir. of Construction | G5: 🟡 In Progress
B6: RISK 4 | C6: Kitchen Cabinet Design | D6: 🟡 Medium | E6: Change Orders Outstanding Change Orders Outstanding Change Orders Outstanding Change Orders Outstanding Change Orders | F6: Dir. of Construction | G6: 🟢 Complete
B7: RISK 5 | C7: Kitchen Cabinet Design | D7: 🟡 Medium | E7: Change Orders Outstanding Change Orders Outstanding Change Orders Outstanding Change Orders Outstanding Change Orders | F7: Dir. of Construction | G7: 🔴 Not Started
B8: RISK 6 | C8: Kitchen Cabinet Design | D8: 🔴 High | E8: Change Orders Outstanding Change Orders Outstanding Change Orders Outstanding Change Orders Outstanding Change Orders | F8: Dir. of Construction | G8: 🔴 Not Started
B9: RISK 7 | C9: Kitchen Cabinet Design | D9: ⚪ Low | E9: Change Orders Outstanding Change Orders Outstanding Change Orders Outstanding Change Orders Outstanding Change Orders | F9: Dir. of Construction | G9: 🔴 Not Started
B10: RISK 8 | C10: Kitchen Cabinet Design | D10: 🟡 Medium | E10: Change Orders Outstanding Change Orders Outstanding Change Orders Outstanding Change Orders Outstanding Change Orders | F10: Dir. of Construction | G10: 🔴 Not Started

Sheet SAFETY
B2: MONTH # | C2: MONTH | D2: HOURS WORKED THIS PERIOD | E2: RECORDABLE INCIDENTS THIS PERIOD | F2: ORIENTATIONS THIS PERIOD | H2: VLN # | I2: VLN Description | J2: VLN Value | K2: Status | L2: VLN Value / Status
B3: Month 1 | C3: 45658 | D3: 862 | E3: 0 | F3: 20 | H3: 1 | J3: 0 | K3: Open | L3: =IF(Table15[[#This Row],[Status]]="Open",Table15[[#This Row],[VLN Value]]," ") -> 0
B4: Month 2 | C4: =EOMONTH(C3,0)+1 -> 45689 | D4: 1924 | E4: 0 | F4: 23 | H4: 2 | J4: 1000 | K4: Open | L4: =IF(Table15[[#This Row],[Status]]="Open",Table15[[#This Row],[VLN Value]]," ") -> 1000
B5: Month 3 | C5: =EOMONTH(C4,0)+1 -> 45717 | D5: 2585 | E5: 0 | F5: 36 | H5: 3 | J5: 0 | K5: Open | L5: =IF(Table15[[#This Row],[Status]]="Open",Table15[[#This Row],[VLN Value]]," ") -> 0
B6: Month 4 | C6: =EOMONTH(C5,0)+1 -> 45748 | D6: 4226 | E6: 1 | F6: 24 | H6: 4 | J6: 0 | K6: Open | L6: =IF(Table15[[#This Row],[Status]]="Open",Table15[[#This Row],[VLN Value]]," ") -> 0
B7: Month 5 | C7: =EOMONTH(C6,0)+1 -> 45778 | D7: =4001+16+178+356+84 -> 4635 | E7: 0 | F7: 17 | H7: 5 | J7: 0 | K7: Open | L7: =IF(Table15[[#This Row],[Status]]="Open",Table15[[#This Row],[VLN Value]]," ") -> 0
B8: Month 6 | C8: =EOMONTH(C7,0)+1 -> 45809 | D8: 99999 | E8: 0 | F8: 0 | H8: 6 | J8: 0 | K8: Open | L8: =IF(Table15[[#This Row],[Status]]="Open",Table15[[#This Row],[VLN Value]]," ") -> 0
B9: Month 7 | C9: =EOMONTH(C8,0)+1 -> 45839 | D9: 0 | E9: 0 | F9: 0 | H9: 7 | J9: 0 | K9: Open | L9: =IF(Table15[[#This Row],[Status]]="Open",Table15[[#This Row],[VLN Value]]," ") -> 0
B10: Month 8 | C10: =EOMONTH(C9,0)+1 -> 45870 | D10: 0 | E10: 0 | F10: 0 | H10: 8 | J10: 0 | K10: Open | L10: =IF(Table15[[#This Row],[Status]]="Open",Table15[[#This Row],[VLN Value]]," ") -> 0
B11: Month 9 | C11: =EOMONTH(C10,0)+1 -> 45901 | D11: 0 | E11: 0 | F11: 0 | H11: 9 | J11: 0 | K11: Open | L11: =IF(Table15[[#This Row],[Status]]="Open",Table15[[#This Row],[VLN Value]]," ") -> 0
B12: Month 10 | C12: =EOMONTH(C11,0)+1 -> 45931 | D12: 0 | E12: 0 | F12: 0 | H12: 10 | J12: 0 | K12: Open | L12: =IF(Table15[[#This Row],[Status]]="Open",Table15[[#This Row],[VLN Value]]," ") -> 0
B13: Month 11 | C13: =EOMONTH(C12,0)+1 -> 45962 | D13: 0 | E13: 0 | F13: 0 | H13: 11 | J13: 0 | K13: Open | L13: =IF(Table15[[#This Row],[Status]]="Open",Table15[[#This Row],[VLN Value]]," ") -> 0
B14: Month 12 | C14: =EOMONTH(C13,0)+1 -> 45992 | D14: 0 | E14: 0 | F14: 0 | H14: 12 | J14: 0 | K14: Open | L14: =IF(Table15[[#This Row],[Status]]="Open",Table15[[#This Row],[VLN Value]]," ") -> 0
B15: Month 13 | C15: =EOMONTH(C14,0)+1 -> 46023 | D15: 0 | E15: 0 | F15: 0 | H15: 13 | J15: 0 | K15: Open | L15: =IF(Table15[[#This Row],[Status]]="Open",Table15[[#This Row],[VLN Value]]," ") -> 0
B16: Month 14 | C16: =EOMONTH(C15,0)+1 -> 46054 | D16: 0 | E16: 0 | F16: 0 | H16: 14 | J16: 0 | K16: Open | L16: =IF(Table15[[#This Row],[Status]]="Open",Table15[[#This Row],[VLN Value]]," ") -> 0
B17: Month 15 | C17: =EOMONTH(C16,0)+1 -> 46082 | D17: 0 | E17: 0 | F17: 0 | H17: 15 | J17: 0 | K17: Open | L17: =IF(Table15[[#This Row],[Status]]="Open",Table15[[#This Row],[VLN Value]]," ") -> 0
B18: Month 16 | C18: =EOMONTH(C17,0)+1 -> 46113 | D18: 0 | E18: 0 | F18: 0 | H18: 16 | J18: 0 | K18: Open | L18: =IF(Table15[[#This Row],[Status]]="Open",Table15[[#This Row],[VLN Value]]," ") -> 0
B19: Month 17 | C19: =EOMONTH(C18,0)+1 -> 46143 | D19: 0 | E19: 0 | F19: 0 | H19: 17 | J19: 0 | K19: Open | L19: =IF(Table15[[#This Row],[Status]]="Open",Table15[[#This Row],[VLN Value]]," ") -> 0
... B25: Month 23 | C25: =EOMONTH(C24,0)+1 -> 46327 | D25: 0 | E25: 0 | F25: 0 | H25: 23 | J25: 0 | K25: Open | L25: =IF(Table15[[#This Row],[Status]]="Open",Table15[[#This Row],[VLN Value]]," ") -> 0
B26: Month 24 | C26: =EOMONTH(C25,0)+1 -> 46357 | D26: 0 | E26: 0 | F26: 0
B27: Month 25 | C27: =EOMONTH(C26,0)+1 -> 46388 | D27: 0 | E27: 0 | F27: 0 | H27: Total | I27: =COUNTA(I3:I26) -> 0 | J27: =SUM(J3:J26) -> 1000 | L27: =SUM(L3:L26) -> 1000
B28: Month 26 | C28: =EOMONTH(C27,0)+1 -> 46419 | D28: 0 | E28: 0 | F28: 0
B29: Month 27 | C29: =EOMONTH(C28,0)+1 -> 46447 | D29: 0 | E29: 0 | F29: 0
B30: Month 28 | C30: =EOMONTH(C29,0)+1 -> 46478 | D30: 0 | E30: 0 | F30: 0
B31: Month 29 | C31: =EOMONTH(C30,0)+1 -> 46508 | D31: 0 | E31: 0 | F31: 0
B32: Month 30 | C32: =EOMONTH(C31,0)+1 -> 46539 | D32: 0 | E32: 0 | F32: 0
B34: TOTAL | D34: =SUM(D3:D33) -> 114231 | E34: =SUM(E3:E33) -> 1 | F34: =SUM(F3:F33) -> 120
B36: TIMEFRAME | C36: CATEGORY | D36: DESCRIPTION/ACTIVITY | E36: STATUS | F36: NOTES/OUTCOME/ACTION | G36: RESPONSIBLE
B37: Lookback | C37: Toolbox Talk – Scheduled | D37: Scaffold Overbuild | E37: 🟢 Completed | F37: Signed off, executed per plan | G37: Asst. Super
B38: Lookback | C38: Notable Visitor – FDNY | D38: Fall Protection | E38: 🟡 Scheduled | F38: 28 attendees, good feedback from field | G38: Dir. of Construction
B39: Lookback | C39: Notable Visitor – FDNY | D39: Heat Stress Awareness | E39: 🟡 Scheduled | F39: Held after near miss, all trades participated | G39: Dir. of Construction
B40: Lookback | C40: Notable Visitor – FDNY | D40: OSHA Informal Walkthrough | E40: 🟡 Scheduled | F40: No citations, documented for record | G40: Dir. of Construction
B41: Lookback | C41: Notable Visitor – FDNY | D41: Concrete Pour – Foundation | E41: 🟡 Scheduled | F41: AHV secured, no issues during extended shift | G41: Dir. of Construction

Sheet QUALITY
B2: MONTH # | C2: MONTH | D2: OBSERVATIONS THIS PERIOD | E2: PUNCHLIST ITEM THIS PERIOD
B3: Month 1 | C3: 45658 | D3: 0 | E3: 0
B4: Month 2 | C4: =EOMONTH(C3,0)+1 -> 45689 | D4: 0 | E4: 0
B5: Month 3 | C5: =EOMONTH(C4,0)+1 -> 45717 | D5: =SAFETY!F5 -> 36 | E5: 0
B6: Month 4 | C6: =EOMONTH(C5,0)+1 -> 45748 | D6: =SAFETY!F6 -> 24 | E6: 0
B7: Month 5 | C7: =EOMONTH(C6,0)+1 -> 45778 | D7: 17 | E7: 0
B8: Month 6 | C8: =EOMONTH(C7,0)+1 -> 45809 | D8: 0 | E8: 0
B9: Month 7 | C9: =EOMONTH(C8,0)+1 -> 45839 | D9: 0 | E9: 0
B10: Month 8 | C10: =EOMONTH(C9,0)+1 -> 45870 | D10: 0 | E10: 0
B11: Month 9 | C11: =EOMONTH(C10,0)+1 -> 45901 | D11: 0 | E11: 0
B12: Month 10 | C12: =EOMONTH(C11,0)+1 -> 45931 | D12: 0 | E12: 0
B13: Month 11 | C13: =EOMONTH(C12,0)+1 -> 45962 | D13: 0 | E13: 0
B14: Month 12 | C14: =EOMONTH(C13,0)+1 -> 45992 | D14: 0 | E14: 0
B15: Month 13 | C15: =EOMONTH(C14,0)+1 -> 46023 | D15: 0 | E15: 0
B16: Month 14 | C16: =EOMONTH(C15,0)+1 -> 46054 | D16: 0 | E16: 0
B17: Month 15 | C17: =EOMONTH(C16,0)+1 -> 46082 | D17: 0 | E17: 0
B18: Month 16 | C18: =EOMONTH(C17,0)+1 -> 46113 | D18: 0 | E18: 0
... B33: Month 31 | C33: =EOMONTH(C32,0)+1 -> 46569 | D33: 0 | E33: 0
B35: TOTAL | D35: =SUM(D3:D34) -> 77 | E35: =SUM(E3:E34) -> 0
C37: Column1 | D37: OBSERVATIONS | E37: PUNCHLIST
C38: AVG. DAYS PAST DUE | D38: 1 | E38: 3
C39: AVG. DAYS TO CLOSE | D39: 2 | E39: 4
B40: RANGE BY ASCENDING OFFENCES | C40: MAIN OFFENDER 1 (SUB NAME) | D40: STNY | E40: STNY
C41: MAIN OFFENDER 2 | D41: ABM | E41: ABM
C42: MAIN OFFENDER 3 | D42: TRYSLER | E42: TRYSLER
C43: MAIN OFFENDER 4 | D43: TRYSLER | E43: TRYSLER
C44: MAIN OFFENDER 5 | D44: TRYSLER | E44: TRYSLER
B47: TIMEFRAME | C47: CATEGORY | D47: DESCRIPTION | E47: TRADE | F47: STATUS | G47: OUTCOME / COMMENTS | H47: RESPONSIBLE | I47: ACTION PLAN
B48: Lookback | C48: Quality – High-Risk Observation | D48: Uneven tile in Unit 405 | E48: TileCo | F48: 🔴 Open | G48: Pending rework | H48: Dir. of Construction | I48: Schedule crew for rework
B49: Lookback | C49: Benchmark – Completed | D49: Tile Mockup | E49: TileCo | F49: 🟢 Passed | G49: Signed off by owner | H49: Dir. of Construction | I49: None
B50: Lookahead | C50: Benchmark – Scheduled | D50: Millwork Mockup | E50: LMN Millwork | F50: 🟡 Scheduled | G50: Pending consultant date | H50: Dir. of Construction | I50: Confirm samples / setup review
B51: Lookback | C51: Delivery – Rejected | D51: HVAC Unit delivery damaged | E51: MechSupplyCo | F51: 🔴 Rejected | G51: Unit returned to vendor | H51: Dir. of Construction | I51: Replacement arriving 6/25
B52: Lookahead | C52: Commissioning – Upcoming | D52: ERV Air Balancing | E52: DEF Mech | F52: 🟡 Scheduled | G52: Coordination with MEP team | H52: Dir. of Construction | I52: Confirm balancing crew
B53: Lookback | C53: Inspection – Special | D53: Concrete Cylinder Break Test | E53: Atlas Eng | F53: 🟢 Passed | G53: Compressive strength verified | H53: Dir. of Construction | I53: None
B54: Lookback | C54: Inspection – NCR | D54: Failed weld at base plate | E54: SteelCo | F54: 🔴 NCR | G54: Reweld scheduled 6/27 | H54: Dir. of Construction | I54: Reinspection on 6/28
B55: Lookback | C55: Inspection – NCR | D55: Failed weld at base plate | E55: SteelCo | F55: 🔴 NCR | G55: Reweld scheduled 6/28 | H55: Dir. of Construction | I55: Reinspection on 6/29
B56: Lookback | C56: Inspection – NCR | D56: Failed weld at base plate | E56: SteelCo | F56: 🔴 NCR | G56: Reweld scheduled 6/29 | H56: Dir. of Construction | I56: Reinspection on 6/30
B57: Lookback | C57: Inspection – NCR | D57: Failed weld at base plate | E57: SteelCo | F57: 🔴 NCR | G57: Reweld scheduled 6/30 | H57: Dir. of Construction | I57: Reinspection on 6/31

Sheet SUBMITTALS & RFI
B2: Trade | C2: Open Critical RFIs | D2: Open Critical Submittals
B3: Electrical | C3: 8 | D3: 3
B4: HVAC | C4: 5 | D4: 2
B5: Windows | C5: 4 | D5: 5
B6: Metals | C6: 4 | D6: 5
B7: Foundation | C7: 4 | D7: 5
B8: Existing Conditions | C8: 4 | D8: 5
B9: Metals | C9: 4 | D9: 5
B10: Conveying Equipment | C10: 4 | D10: 5
B11: Exterior Improvements | C11: 4 | D11: 5
C12: 0 | D12: 0
C13: 0 | D13: 0

Sheet FINANCIALS
B2: DESCRIPTION | C2: THIS PERIOD | D2: LAST PERIOD | E2: & DIF
B3: Original Contract Amt. | C3: 8800000
B4: Current Contract Amt. | C4: 9116960.5 | D4: 9014313 | E4: =IF(Table8[[#This Row],[THIS PERIOD]]="N/A","",(Table8[[#This Row],[THIS PERIOD]]-D4)/D4) -> 0.011387166
B5: Pending CO's | C5: =65000+3158.46+11550+4620 -> 84328.46 | D5: 234983 | E5: =IF(Table8[[#This Row],[THIS PERIOD]]="N/A","",(Table8[[#This Row],[THIS PERIOD]]-D5)/D5) -> -0.64112953
B6: Age of oldest unapproved CO | C6: 1 | D6: 1 | E6: =IF(Table8[[#This Row],[THIS PERIOD]]="N/A","",(Table8[[#This Row],[THIS PERIOD]]-D6)/D6) -> 0
B7: Profitability | C7: Margin fade but no plan | D7: Within Range | G7: Based on the original financial projection
B8: Cash Position | C8: < 50% = 🔴 Bad Cash Position | D8: < 50% = 🔴 Bad Cash Position | G8: ≥ 100% = 🟢 Good Cash Position; 50% – 99% = 🟡 Medium / Watch Zone; < 50% = 🔴 Bad Cash Position; Metric Cash Collected = $2,000,000 AR Outstanding = $400,000 Remaining Forecasted Cost = $1,500,000 Cash Position % = ($2,000,000 + $400,000) ÷ $1,500,000 × 100 = 160%
B9: Remaining in Contingency | C9: N/A | D9: N/A | E9: =IF(Table8[[#This Row],[THIS PERIOD]]="N/A","",(Table8[[#This Row],[THIS PERIOD]]-D9)/D9)
B10: Total Billed | C10: =3032804.23-35000 -> 2997804.2 | D10: 2344355.7 | E10: =IF(Table8[[#This Row],[THIS PERIOD]]="N/A","",(Table8[[#This Row],[THIS PERIOD]]-D10)/D10) -> 0.27873267
B11: Bill This Pay Period | C11: 400000
B12: Total Paid | C12: 2683097.5 | D12: 1960036.6 | E12: =IF(Table8[[#This Row],[THIS PERIOD]]="N/A","",(Table8[[#This Row],[THIS PERIOD]]-D12)/D12) -> 0.36890173
B13: Remaining Balance | C13: 6433863 | D13: 6669957.3 | E13: =IF(Table8[[#This Row],[THIS PERIOD]]="N/A","",(Table8[[#This Row],[THIS PERIOD]]-D13)/D13) -> -0.03539667
B14: Retainage | C14: 127441.56 | D14: 97614.85 | E14: =IF(Table8[[#This Row],[THIS PERIOD]]="N/A","",(Table8[[#This Row],[THIS PERIOD]]-D14)/D14) -> 0.30555505
B15: Cost to Complete | C15: 6786492.3 | D15: 6717008.2 | E15: =IF(Table8[[#This Row],[THIS PERIOD]]="N/A","",(Table8[[#This Row],[THIS PERIOD]]-D15)/D15) -> 0.010344498
B18: MONTH | C18: BUDGET | D18: FORECAST | E18: SPENT TO DATE2 | F18: STATUS | H18: Variance (Budget - Actual) | I18: RAG Status | J18: Meaning
B19: General Requirements | C19: 299746.97 | D19: 89149.77 | E19: 15000 | F19: 🔴 Over Budget | H19: ≥ 0% | I19: 🟢 On Track / Positive | J19: Under or exactly on budget (great)
B20: General Conditions | C20: 850018.69 | D20: 323265.39 | E20: 20000 | F20: 🟢 On Track | H20: -0.01% to -5% | I20: 🟡 Watch | J20: Slight overrun, monitor
H21: > -5% | I21: 🔴 Over Budget | J21: Significant overrun, needs correction
B24: MONTH # | C24: MONTH | D24: INVOICE SENT | E24: INVOICE PAID | F24: DELTA | H24: MONTH # | I24: MONTH | J24: OT HOURS WORKED THIS PERIOD
B25: Month 1 | C25: 45962 | D25: 45603 | E25: 45610 | F25: =IF(Table11012[[#This Row],[INVOICE PAID]]>0,Table11012[[#This Row],[INVOICE PAID]]-Table11012[[#This Row],[INVOICE SENT]],"") -> 7 | H25: Month 1 | I25: 45658 | J25: 12
B26: Month 2 | C26: =EOMONTH(C25,0)+1 -> 45992 | D26: 45616 | E26: 45628 | F26: =IF(Table11012[[#This Row],[INVOICE PAID]]>0,Table11012[[#This Row],[INVOICE PAID]]-Table11012[[#This Row],[INVOICE SENT]],"") -> 12 | H26: Month 2 | I26: =EOMONTH(I25,0)+1 -> 45689 | J26: 18
B27: Month 3 | C27: =EOMONTH(C26,0)+1 -> 46023 | D27: 45646 | E27: 45657 | F27: =IF(Table11012[[#This Row],[INVOICE PAID]]>0,Table11012[[#This Row],[INVOICE PAID]]-Table11012[[#This Row],[INVOICE SENT]],"") -> 11 | H27: Month 3 | I27: =EOMONTH(I26,0)+1 -> 45717 | J27: 18
B28: Month 4 | C28: =EOMONTH(C27,0)+1 -> 46054 | D28: 45688 | E28: 45688 | F28: =IF(Table11012[[#This Row],[INVOICE PAID]]>0,Table11012[[#This Row],[INVOICE PAID]]-Table11012[[#This Row],[INVOICE SENT]],"") -> 0 | H28: Month 4 | I28: =EOMONTH(I27,0)+1 -> 45748 | J28: 21
B29: Month 5 | C29: =EOMONTH(C28,0)+1 -> 46082 | D29: 45719 | E29: 45722 | F29: =IF(Table11012[[#This Row],[INVOICE PAID]]>0,Table11012[[#This Row],[INVOICE PAID]]-Table11012[[#This Row],[INVOICE SENT]],"") -> 3 | H29: Month 5 | I29: =EOMONTH(I28,0)+1 -> 45778 | J29: 43.5
B30: Month 6 | C30: =EOMONTH(C29,0)+1 -> 46113 | D30: 45719 | E30: 45723 | F30: =IF(Table11012[[#This Row],[INVOICE PAID]]>0,Table11012[[#This Row],[INVOICE PAID]]-Table11012[[#This Row],[INVOICE SENT]],"") -> 4 | H30: Month 6 | I30: =EOMONTH(I29,0)+1 -> 45809
B31: Month 7 | C31: =EOMONTH(C30,0)+1 -> 46143 | D31: 45741 | E31: 45749 | F31: =IF(Table11012[[#This Row],[INVOICE PAID]]>0,Table11012[[#This Row],[INVOICE PAID]]-Table11012[[#This Row],[INVOICE SENT]],"") -> 8 | H31: Month 7 | I31: =EOMONTH(I30,0)+1 -> 45839
B32: Month 8 | C32: =EOMONTH(C31,0)+1 -> 46174 | D32: 45741 | E32: 45763 | F32: =IF(Table11012[[#This Row],[INVOICE PAID]]>0,Table11012[[#This Row],[INVOICE PAID]]-Table11012[[#This Row],[INVOICE SENT]],"") -> 22 | H32: Month 8 | I32: =EOMONTH(I31,0)+1 -> 45870
B33: Month 9 | C33: =EOMONTH(C32,0)+1 -> 46204 | D33: 45772 | E33: 45779 | F33: =IF(Table11012[[#This Row],[INVOICE PAID]]>0,Table11012[[#This Row],[INVOICE PAID]]-Table11012[[#This Row],[INVOICE SENT]],"") -> 7 | H33: Month 9 | I33: =EOMONTH(I32,0)+1 -> 45901
B34: Month 10 | C34: =EOMONTH(C33,0)+1 -> 46235 | D34: 45772 | E34: 45790 | F34: =IF(Table11012[[#This Row],[INVOICE PAID]]>0,Table11012[[#This Row],[INVOICE PAID]]-Table11012[[#This Row],[INVOICE SENT]],"") -> 18 | H34: Month 10 | I34: =EOMONTH(I33,0)+1 -> 45931
B35: Month 11 | C35: =EOMONTH(C34,0)+1 -> 46266 | D35: 45806 | E35: 45811 | F35: =IF(Table11012[[#This Row],[INVOICE PAID]]>0,Table11012[[#This Row],[INVOICE PAID]]-Table11012[[#This Row],[INVOICE SENT]],"") -> 5 | H35: Month 11 | I35: =EOMONTH(I34,0)+1 -> 45962
B36: Month 12 | C36: =EOMONTH(C35,0)+1 -> 46296 | F36: =IF(Table11012[[#This Row],[INVOICE PAID]]>0,Table11012[[#This Row],[INVOICE PAID]]-Table11012[[#This Row],[INVOICE SENT]],"") | H36: Month 12 | I36: =EOMONTH(I35,0)+1 -> 45992
B37: Month 13 | C37: =EOMONTH(C36,0)+1 -> 46327 | F37: =IF(Table11012[[#This Row],[INVOICE PAID]]>0,Table11012[[#This Row],[INVOICE PAID]]-Table11012[[#This Row],[INVOICE SENT]],"") | H37: Month 13 | I37: =EOMONTH(I36,0)+1 -> 46023
B38: Month 14 | C38: =EOMONTH(C37,0)+1 -> 46357 | F38: =IF(Table11012[[#This Row],[INVOICE PAID]]>0,Table11012[[#This Row],[INVOICE PAID]]-Table11012[[#This Row],[INVOICE SENT]],"") | H38: Month 14 | I38: =EOMONTH(I37,0)+1 -> 46054
B39: Month 15 | C39: =EOMONTH(C38,0)+1 -> 46388 | F39: =IF(Table11012[[#This Row],[INVOICE PAID]]>0,Table11012[[#This Row],[INVOICE PAID]]-Table11012[[#This Row],[INVOICE SENT]],"") | H39: Month 15 | I39: =EOMONTH(I38,0)+1 -> 46082
B40: Month 16 | C40: =EOMONTH(C39,0)+1 -> 46419 | F40: =IF(Table11012[[#This Row],[INVOICE PAID]]>0,Table11012[[#This Row],[INVOICE PAID]]-Table11012[[#This Row],[INVOICE SENT]],"") | H40: Month 16 | I40: =EOMONTH(I39,0)+1 -> 46113
B41: Month 17 | C41: =EOMONTH(C40,0)+1 -> 46447 | F41: =IF(Table11012[[#This Row],[INVOICE PAID]]>0,Table11012[[#This Row],[INVOICE PAID]]-Table11012[[#This Row],[INVOICE SENT]],"") | H41: Month 17 | I41: =EOMONTH(I40,0)+1 -> 46143
B42: Month 18 | C42: =EOMONTH(C41,0)+1 -> 46478 | F42: =IF(Table11012[[#This Row],[INVOICE PAID]]>0,Table11012[[#This Row],[INVOICE PAID]]-Table11012[[#This Row],[INVOICE SENT]],"") | H42: Month 18 | I42: =EOMONTH(I41,0)+1 -> 46174
B43: Month 19 | C43: =EOMONTH(C42,0)+1 -> 46508 | F43: =IF(Table11012[[#This Row],[INVOICE PAID]]>0,Table11012[[#This Row],[INVOICE PAID]]-Table11012[[#This Row],[INVOICE SENT]],"") | H43: Month 19 | I43: =EOMONTH(I42,0)+1 -> 46204
B44: Month 20 | C44: =EOMONTH(C43,0)+1 -> 46539 | F44: =IF(Table11012[[#This Row],[INVOICE PAID]]>0,Table11012[[#This Row],[INVOICE PAID]]-Table11012[[#This Row],[INVOICE SENT]],"") | H44: Month 20 | I44: =EOMONTH(I43,0)+1 -> 46235
B45: Month 21 | C45: =EOMONTH(C44,0)+1 -> 46569 | F45: =IF(Table11012[[#This Row],[INVOICE PAID]]>0,Table11012[[#This Row],[INVOICE PAID]]-Table11012[[#This Row],[INVOICE SENT]],"") | H45: Month 21 | I45: =EOMONTH(I44,0)+1 -> 46266
...

Sheet SCORECARD CALC
B2: PROJECT SCORE
B3: DESCRIPTION | C3: SCORE | D3: METRICS | E3: PROJECT SCORE | F3: WEIGHTING | G3: OVERALL SCORE
B4: Accounts Receivable | C4: 3 | D4: < 45 | E4: =IF(DASHBOARD!AT25<45,'SCORECARD CALC'!C4,IF(DASHBOARD!AT25<60,'SCORECARD CALC'!C5,IF(DASHBOARD!AT25>=60,'SCORECARD CALC'!C6,0))) -> 3 | F4: 0.12 | G4: =((E4*F4))/3 -> 0.12
C5: 2 | D5: 46-60
C6: 0 | D6: 61-75
B7: Profitability | C7: 3 | D7: Within Range | E7: =IF(FINANCIALS!C7=DROPDOWN!Q4,'SCORECARD CALC'!C7,IF(FINANCIALS!C7=DROPDOWN!Q5,'SCORECARD CALC'!C8,IF(FINANCIALS!C7=DROPDOWN!Q6,'SCORECARD CALC'!C9,0))) -> 0 | F7: 0.12 | G7: =((E7*F7))/3 -> 0
C8: 2 | D8: Out of Range, but has a plan
C9: 0 | D9: Margin fade but no plan
B10: Cash Position | C10: 3 | D10: ≥ 100% | E10: =IF(DASHBOARD!AS31=DROPDOWN!P4,'SCORECARD CALC'!C10,IF(DASHBOARD!AS31=DROPDOWN!P5,'SCORECARD CALC'!C11,IF(DASHBOARD!AS31=DROPDOWN!P6,'SCORECARD CALC'!C12,0))) -> 0 | F10: 0.12 | G10: =((E10*F10))/3 -> 0
C11: 2 | D11: 50% – 99%
C12: 0 | D12: < 50%
B13: Change Orders (Avg Days Open) | C13: 3 | D13: < 45 | E13: =IF(DASHBOARD!AT21<=45,'SCORECARD CALC'!C13,IF(DASHBOARD!AT21<60,'SCORECARD CALC'!C14,IF(DASHBOARD!AT21>=60,'SCORECARD CALC'!C15,0))) -> 3 | F13: 0.08 | G13: =((E13*F13))/3 -> 0.08
C14: 2 | D14: 46-60
C15: 0 | D15: 61-75
B16: Safety incidents | C16: 3 | D16: No Incidents | E16: =IF(DASHBOARD!AI51=0,'SCORECARD CALC'!C16,IF(DASHBOARD!AI51<=1,'SCORECARD CALC'!C17,IF(DASHBOARD!AI51>=2,'SCORECARD CALC'!C18,0))) -> 3 | F16: 0.14 | G16: =((E16*F16))/3 -> 0.14
C17: 2 | D17: < 1 Incidents
C18: 0 | D18: 2+ Incidents
B19: Schedule Performance (Critcal Missed Starts) | C19: 3 | D19: <5% | E19: =IF(DASHBOARD!L19<=5,'SCORECARD CALC'!C19,IF(DASHBOARD!L19<=9,'SCORECARD CALC'!C20,IF(DASHBOARD!L19>=10,'SCORECARD CALC'!C21,0))) -> 3 | F19: 0.15 | G19: =((E19*F19))/3 -> 0.15
C20: 2 | D20: 6-9%
C21: 0 | D21: 10%+
B22: Completion Variance | C22: 3 | D22: 0 or - Days | E22: =IF(DASHBOARD!M16<=0,'SCORECARD CALC'!C22,IF(DASHBOARD!M16<=14,'SCORECARD CALC'!C23,IF(DASHBOARD!M16>=15,'SCORECARD CALC'!C24,0))) -> 0 | F22: 0.15 | G22: =((E22*F22))/3 -> 0
C23: 2 | D23: 1-14 Days
C24: 0 | D24: 15+ Days
B25: Observations (Avg Days Open) | C25: 3 | D25: <5 Days | E25: =IF(DASHBOARD!M67<=5,'SCORECARD CALC'!C25,IF(DASHBOARD!M67<=10,'SCORECARD CALC'!C26,IF(DASHBOARD!M67>=11,'SCORECARD CALC'!C27,0))) -> 3 | F25: 0.1 | G25: =((E25*F25))/3 -> 0.1
C26: 2 | D26: 6-10 Days
C27: 0 | D27: 11+
B28: Daily Reports (# of reports not complete and distributed on Same Day) | C28: 3 | D28: <2 | E28: 0 | F28: 0.02 | G28: =((E28*F28))/3 -> 0
C29: 2 | D29: 3-4 | I29: MANUAL INPUT
C30: 0 | D30: 5+
G31: =SUM(G4:G30) -> 0.59
B33: CLIENT SATISFACTION
B34: WHO WAS SURVEYED: | C34: ANONYMOUS | F34: MANUAL INPUT
B35: QUESTIONS | C35: SCORE (1 to 5)
B36: Q1 | C36: 3
B37: Q2 | C37: 3
B38: Q3 | C38: 3 | F38: MANUAL INPUT
B39: Q4 | C39: 3
B40: Q5 | C40: 3
B41: Q6 | C41: 3
C42: =SUM(C36:C41)/(COUNTA(B36:B41)*5) -> 0.6

Sheet DROPDOWN
B2: RISKS TAB | E2: SCHEDULE | H2: SAFETY | K2: QUALITY | M2: SUBMITTALS & RFIS | N2: FINANCIAL
B3: IMPACTS | C3: OWNER | D3: STATUS | E3: STATUS SUMMARY | F3: APPROVED | G3: REVISION | H3: TIMEFRAME | I3: CATEGORY | J3: STATUS | K3: CATEGORY | L3: STATUS | M3: TRADES | N3: FORECAST | O3: APPROVED | P3: APPROVED | Q3: PROFITABILITY
B4: 🔴 High | C4: Scheduler | D4: 🔴 Not Started | E4: 🟢 On Track | F4: 🟢 Y | G4: Rev#1 | H4: Lookback | I4: High-Risk Item – Completed | J4: 🟢 Completed | K4: Quality – High-Risk Observation | L4: 🔴 Open | M4: Existing Conditions | N4: 🟢 On Track | O4: 🟢 Y | P4: ≥ 100% = 🟢 Good Cash Position | Q4: Within Range
B5: 🟡 Medium | C5: PM | D5: 🟡 Planned | E5: 🟡 Behind | F5: 🔴 N | G5: Rev#2 | H5: Lookahead | I5: High-Risk Item – Upcoming | J5: 🟢 Positive | K5: Benchmark – Completed | L5: 🟢 Passed | M5: Concrete | N5: 🟡 Watch | O5: 🔴 N | P5: 50% – 99% = 🟡 Medium / Watch Zone | Q5: Out of Range, but has a plan
B6: ⚪ Low | C6: Asst. Super | D6: 🟡 In Progress | E6: 🔴 At Risk | G6: Rev#3 | I6: Toolbox Talk – Completed | J6: 🟡 Scheduled | K6: Benchmark – Scheduled | L6: 🟡 Scheduled | M6: Foundation | N6: 🔴 Over Budget | P6: < 50% = 🔴 Bad Cash Position | Q6: Margin fade but no plan
C7: Asst. PM | D7: 🟢 Complete | G7: Rev#4 | I7: Toolbox Talk – Scheduled | J7: 🟡 Planned | K7: Mockup – Completed | L7: 🔴 Rejected | M7: Superstructure
C8: Super | G8: Rev#5 | I8: Safety Standdown – Completed | J8: 🔴 High Risk | K8: Mockup – Scheduled | L8: 🟡 Scheduled | M8: Masonry
C9: Senior PM | G9: Rev#6 | I9: Safety Standdown – Scheduled | J9: 🔴 Delayed | K9: Delivery – Rejected | L9: 🟢 Passed | M9: Metals
C10: PX | G10: Rev#7 | I10: Weekend/OT Work – Completed | K10: Delivery – Upcoming | L10: 🔴 NCR | M10: Drywall & Carpentry
C11: Dir. of Construction | G11: Rev#8 | I11: Weekend/OT Work – Planned | K11: Commissioning – Completed | M11: Roofing
C12: Principal | G12: Rev#9 | I12: Notable Visitor – DOB | K12: Commissioning – Upcoming | M12: Millwork
G13: Rev#10 | I13: Notable Visitor – FDNY | K13: Inspection – Special | M13: Finishes
G14: Rev#11 | I14: Notable Visitor – Client | K14: Inspection – NCR | M14: Specialties
I15: Notable Visitor – OSHA | M15: Equipment
I16: Notable Visitor – Other | M16: Doors & Frames
I17: Safety Win – Team Performance | M17: Glass & Glazing
I18: Safety Win – Milestone with No Incidents | M18: Conveying Equipment
I19: Safety Win – Inspection Success | M19: Sprinkler
M20: Plumbing
M21: HVAC
M22: Building Automation Systems
M23: Electrical
M24: Low Voltage
M25: Utilities
M26: Painting
M27: Flooring
M28: Self Levelling
M29: Windows
M30: Lighting
M31: Exterior Improvements
