Workbook

Sheet COVER
A1: PROJECT QUALITY PLAN (PQP)
A2: SaunaLounge — 45 South 3rd Street, Ground Floor, Brooklyn NY 11249
A3: Project-Specific QA/QC, Special Inspection & Statutory Sign-Off Plan
A5: A1 — PROJECT OVERVIEW
A6: Project Name | B6: SaunaLounge
A7: Project Location | B7: 45 South 3rd Street, Ground Floor, Brooklyn, NY 11249 — within The 360 Wythe Condominium
A8: Project Type | B8: Ground-floor interior tenant fitout — 5,783 SF wellness / spa (sauna, cold plunge, pool, locker rooms, lounge, bar, kitchen)
A9: Owner / Client | B9: Saunalounge, LLC (Teal Development / JLKing Consulting) | C9: Client Rep: Jeffrey Aser, Teal Development Partners — 914.319.7493, jeff@tealdevelopment.com
A10: Landlord / Condominium | B10: FREEWYTHE, LLC | The 360 Wythe Condominium Board of Managers
A11: Construction Manager | B11: Affect Build, LLC — 389 5th Avenue, Suite 504, New York, NY 10016
A12: Contract Type | B12: AIA Document A104™–2017, Standard Abbreviated Form, Exhibits A–I
A13: Contract Sum | B13: $3,526,451.50 (incl. $247,968.00 Limited Work / early-release HVAC)
A14: Contract Executed | B14: Owner 6/19/2026 | Contractor 6/22/2026
A15: Project Duration | B15: 6/19/2026 – 1/6/2027 (144 calendar days; 3 weeks preconstruction + 26 weeks on site)
A16: Target Substantial Completion | B16: 46377
A17: Affect Build Job Number
A18: DOB Job / Filing Number
A20: PROJECT QUALITY TEAM (Q-TEAM)
A21: Project Manager | B21: Illeana Aguire | C21: QA owner: ensures submittals / shop drawings approved prior to procurement and installation; engages testing and inspection agencies; issues NCRs
A22: Site Superintendent | B22: Nicholas Scarmacca | C22: QC owner in the field: on-site QC lead; coordinates inspections 48–72 hrs in advance; verifies readiness; maintains the inspector sign-in log
A23: Assistant Project Manager | B23: Hugh McDonagh | C23: Maintains submittal, ITP and inspection registers in Procore; tracks report receipt and closure
A24: Director of Construction | B24: Enda Forrey | C24: Accountability: verifies benchmarks are established and documented, quality records maintained and procedures followed; escalation point for repeat deficiencies
A25: Architect of Record | B25: Colberg Architecture | C25: Required at First Work Review for Tier 3 / Tier 4 DFOWs
A26: MEP / FP Engineer | B26: Collectif | C26: TR8 mechanical / energy code special inspections
A27: Special Inspections Agency | B27: CodeGreen Inspection (CGI) | C27: TR1 / TR2 / TR3 / TR8 · Matrix ref. 2026-0401 · 12 budgeted site visits · allow min. 2–3 days to schedule
A28: Testing Laboratory | C28: Concrete testing — to be engaged; enter laboratory name
A29: Commissioning Agent | C29: Owner's CA if appointed
A30: Owner's Separate Trades | B30: Pool shell, sauna assemblies, cold plunge basin (Contract §12.4) | C30: Affect Build provides rough-in, coordination and finish trades only; inspects its own interfaces
A32: GOVERNING DOCUMENTS & HIERARCHY
A33: 1 | B33: Contract Documents — AIA A104–2017 and Exhibits A–I | C33: Order of precedence per CMP §2.2
A34: 2 | B34: Vision Zero QA/QC Playbook v2.0 (governing quality document) | C34: Supersedes all prior QA/QC guidance
A35: 3 | B35: Construction Management Plan — SaunaLounge (DRAFT) | C35: Sections 7, 8, 9, 12, 19, 20
A36: 4 | B36: Affect Trainual SOPs — Quality Management; Submittals & Inspections | C36: Read alongside the Playbook
A37: 5 | B37: NYC Building Code Chapter 17 (Special Inspections) and Chapter 33 | C37: TR1 / TR8 filings via DOB NOW
A38: 6 | B38: NYC DOH Pool / Spa requirements; FDNY rules; NFPA 13 and NFPA 72 | C38: Life safety and pool sign-off
A40: QUALITY FRAMEWORK — HOW THIS WORKBOOK IS USED
A41: Four Phases of Control | B41: Every DFOW: Phase 1 Preparatory → Phase 2 Work Readiness → Phase 3 First Work Review → Phase 4 Follow-Up | C41: Tracked on the DFOW Risk Register
A42: DFOW Risk Tiers | B42: Tier 4 Critical (daily follow-up, dual sign-off) · Tier 3 High (every other day, A/E at First Work Review) · Tier 2 Moderate (weekly) · Tier 1 Low (at completion) | C42: Tier drives inspection intensity
A43: Hold vs Witness Points | B43: HOLD — work stops until signed off, no exceptions. WITNESS — 48 hrs notice; work may proceed if witness does not attend after written notice | C43: Defined per test on the ITP
A44: Benchmark Hold Points (CMP §8.4) | B44: Pre-cover before drywall · Waterproofing before backfill at pool equipment room · Above-ceiling before tile / grid close-up · Interface at Owner's pool / sauna assemblies | C44: Non-negotiable
...

Sheet DASHBOARD
A1: QA/QC MASTER TRACKER — SAUNALOUNGE, 45 SOUTH 3RD STREET
A2: Comprehensive roll-up of Quality, Special and Statutory inspections. All figures are live formulas driven by the register tabs — update the registers, not this page.
A4: A. PROGRAMME READINESS — STATUTORY, SPECIAL & QUALITY REGISTERS
A5: Register | B5: Total | C5: Complete / Passed | D5: Open / Outstanding | E5: Failed / Blocked | F5: % Complete | G5: Where to update
A6: Path to TCO — statutory gates | B6: ='Path to TCO'!E4 -> 46 | C6: ='Path to TCO'!G4 -> 0 | D6: ='Path to TCO'!I4 -> 46 | E6: =COUNTIF('Path to TCO'!I9:I70,"Blocked") -> 0 | F6: ='Path to TCO'!K4 -> 0 | G6: Path to TCO tab
A7: Path to Fire Alarm — FDNY LOA steps | B7: =COUNTA('Path to Fire Alarm'!A8:A30) -> 23 | C7: =COUNTIF('Path to Fire Alarm'!H8:H30,"Complete") -> 0 | D7: =B7-C7 -> 23 | E7: =COUNTIF('Path to Fire Alarm'!H8:H30,"Failed - Re-test")+COUNTIF('Path to Fire Alarm'!H8:H30,"Blocked") -> 0 | F7: =IF(B7=0,0,C7/B7) -> 0 | G7: Path to Fire Alarm tab
A8: Statutory inspections & agency approvals | B8: ='Statutory Inspections'!B4 -> 24 | C8: =COUNTIF('Statutory Inspections'!M7:M40,"Closed") -> 0 | D8: =B8-C8 -> 24 | E8: ='Statutory Inspections'!F4 -> 0 | F8: =IF(B8=0,0,C8/B8) -> 0 | G8: Statutory Inspections tab
A9: Special inspections (NYC BC Ch.17 — TR forms) | B9: ='Special Inspections'!B4 -> 36 | C9: =COUNTIF('Special Inspections'!P7:P45,"Closed") -> 0 | D9: =B9-C9 -> 36 | E9: ='Special Inspections'!F4 -> 0 | F9: =IF(B9=0,0,C9/B9) -> 0 | G9: Special Inspections tab
A10: ITP — tests & inspections | B10: =COUNTA(ITP!A5:A35) -> 31 | C10: =COUNTIF(ITP!L5:L35,"Pass") -> 0 | D10: =B10-C10 -> 31 | E10: =COUNTIF(ITP!L5:L35,"Fail") -> 0 | F10: =IF(B10=0,0,C10/B10) -> 0 | G10: ITP tab
A11: Commissioning & turnover — systems accepted | B11: =Commissioning!B4 -> 38 | C11: =COUNTIF(Commissioning!P7:P50,"Accepted") -> 0 | D11: =B11-C11 -> 38 | E11: =COUNTIF(Commissioning!J7:J50,"Fail") -> 0 | F11: =IF(B11=0,0,C11/B11) -> 0 | G11: Commissioning tab
A12: Submittals, samples & mock-ups | B12: ='Submittals & Mockups'!B4 -> 39 | C12: ='Submittals & Mockups'!D4 -> 0 | D12: ='Submittals & Mockups'!I4 -> 39 | E12: ='Submittals & Mockups'!G4 -> 0 | F12: =IF(B12=0,0,C12/B12) -> 0 | G12: Submittals & Mockups tab
A13: DFOW register — Phase 4 follow-up complete | B13: =COUNTA('DFOW Risk Register'!A5:A36) -> 32 | C13: =COUNTIF('DFOW Risk Register'!P5:P36,"Complete") -> 0 | D13: =B13-C13 -> 32 | E13: 0 | F13: =IF(B13=0,0,C13/B13) -> 0 | G13: DFOW Risk Register tab
A14: Trade QC checklists — line items | B14: =$D$59 -> 625 | C14: =$E$59 -> 0 | D14: =B14-C14 -> 625 | E14: =$F$59 -> 0 | F14: =IF(B14=0,0,C14/B14) -> 0 | G14: 26 trade checklist tabs
A15: DOH compliance checklist (pool / spa + Article 81 food service) | B15: ='DOH Checklist'!B4 -> 101 | C15: ='DOH Checklist'!D4 -> 0 | D15: ='DOH Checklist'!F4 -> 101 | E15: =COUNTIF('DOH Checklist'!F7:F130,"Query Raised") -> 0 | F15: ='DOH Checklist'!J4 -> 0 | G15: DOH Checklist tab — first pass; numeric criteria require confirmation by the Owner's DOH consultant
A16: B. CRITICAL DATES & QUALITY EXCEPTIONS
A17: Metric | B17: Value | G17: Standard / Action
A18: Target Substantial Completion | B18: ='Path to TCO'!C4 -> 46377 | G18: Per Exhibit E — CMP §2.1
A19: Calendar days remaining to Substantial Completion | B19: =B18-TODAY() -> 129 | G19: Live countdown
A20: Latest permissible FDNY fire alarm witness test date | B20: ='Path to Fire Alarm'!H4 -> 46363 | G20: CMP §20.1 — minimum 2 weeks before SC to allow re-tests
A21: TCO readiness | B21: ='Path to TCO'!K4 -> 0 | G21: All gates must reach Complete before TCO filing
A22: Open NCRs / corrective actions | B22: ='NCR Log'!D4 -> 0 | G22: Target ZERO. NCRs must close before the next progress billing is approved
A23: NCRs past target close date | B23: ='NCR Log'!H4 -> 0 | G23: Escalate: 3-5 working days standard; Tier 4 within 72 hours
A24: Average days to close an NCR | B24: ='NCR Log'!K4 -> — | G24: Tracked weekly at Q-Team meeting
A25: Open punch / RCL items | B25: ='Punch & RCL Log'!D4 -> 0 | G25: Zero Punch is the objective (Playbook A9)
A26: Open punch items with life-safety / occupancy impact | B26: ='Punch & RCL Log'!I4 -> 0 | G26: Correct within 48 hours
A27: Punch items aged over 7 days | B27: ='Punch & RCL Log'!L4 -> 0 | G27: Beyond 5 days escalate to trade PM; beyond 7 days to trade executive
A28: Inspector sign-in entries recorded | B28: =COUNTA('Inspector Sign-In'!A5:A120) -> 0 | G28: Mandatory for every DOB / FDNY / DOH / SIA / lab visit
A29: Tier 3 & Tier 4 DFOWs (elevated control) | B29: =COUNTIF('DFOW Risk Register'!C5:C36,4)+COUNTIF('DFOW Risk Register'!C5:C36,3) -> 17 | G29: Daily / every-other-day follow-up required
A30: CodeGreen (CGI) budgeted special inspection visits remaining | B30: ='Special Inspections'!G60 -> 12 | G30: 12 visits budgeted per CGI matrix 2026-0401. Log each visit used on the Special Inspections tab (row 50-59)
A31: C. TRADE QC CHECKLIST ROLL-UP — 26 PROJECT-SPECIFIC CHECKLISTS
A32: Trade Checklist Tab | B32: DFOW Ref | C32: Risk Tier | D32: Checklist Items | E32: Pass | F32: Fail | G32: % Complete
A33: Excavation | B33: D-08 | C33: 3 | D33: =Excavation!D6 -> 19 | E33: =Excavation!F6 -> 0 | F33: =Excavation!H6 -> 0 | G33: =IF($D33=0,0,Excavation!J6) -> 0
A34: Concrete Formwork | B34: D-07 | C34: 3 | D34: ='Concrete Formwork'!D6 -> 25 | E34: ='Concrete Formwork'!F6 -> 0 | F34: ='Concrete Formwork'!H6 -> 0 | G34: =IF($D34=0,0,'Concrete Formwork'!J6) -> 0
A35: Conc Reinforcement | B35: D-07 | C35: 3 | D35: ='Conc Reinforcement'!D6 -> 26 | E35: ='Conc Reinforcement'!F6 -> 0 | F35: ='Conc Reinforcement'!H6 -> 0 | G35: =IF($D35=0,0,'Conc Reinforcement'!J6) -> 0
A36: CIP Concrete | B36: D-07 | C36: 3 | D36: ='CIP Concrete'!D6 -> 28 | E36: ='CIP Concrete'!F6 -> 0 | F36: ='CIP Concrete'!H6 -> 0 | G36: =IF($D36=0,0,'CIP Concrete'!J6) -> 0
A37: Precast Concrete | B37: D-07 | C37: 3 | D37: ='Precast Concrete'!D6 -> 21 | E37: ='Precast Concrete'!F6 -> 0 | F37: ='Precast Concrete'!H6 -> 0 | G37: =IF($D37=0,0,'Precast Concrete'!J6) -> 0
A38: Unit Masonry | B38: D-19 | C38: 2 | D38: ='Unit Masonry'!D6 -> 31 | E38: ='Unit Masonry'!F6 -> 0 | F38: ='Unit Masonry'!H6 -> 0 | G38: =IF($D38=0,0,'Unit Masonry'!J6) -> 0
A39: Metal Deck | B39: D-18 | C39: 2 | D39: ='Metal Deck'!D6 -> 30 | E39: ='Metal Deck'!F6 -> 0 | F39: ='Metal Deck'!H6 -> 0 | G39: =IF($D39=0,0,'Metal Deck'!J6) -> 0
A40: Slab on Grade | B40: D-07 | C40: 3 | D40: ='Slab on Grade'!D6 -> 19 | E40: ='Slab on Grade'!F6 -> 0 | F40: ='Slab on Grade'!H6 -> 0 | G40: =IF($D40=0,0,'Slab on Grade'!J6) -> 0
A41: Slab on Deck | B41: D-07 | C41: 3 | D41: ='Slab on Deck'!D6 -> 13 | E41: ='Slab on Deck'!F6 -> 0 | F41: ='Slab on Deck'!H6 -> 0 | G41: =IF($D41=0,0,'Slab on Deck'!J6) -> 0
...

Sheet Project Identifiers
A1: SAUNALOUNGE — PROJECT IDENTIFIERS & Q-TEAM RESPONSIBILITY MATRIX
A2: 45 South 3rd Street, Ground Floor, Brooklyn NY 11249 | Affect Build, LLC | Precon tool used to fix roles and responsibilities of the Q-Team. The Q-Team then collaboratively populates the QA activity matrix below, which drives the Checklist, NCR, Control Samples, Mock-Ups, Punchlist Walks and Monthly QA Reviews.
A4: A. Q-TEAM MEMBERS & RESPONSIBILITIES
A5: Role | B5: Name
A6: Project Manager | B6: Illeana Aguire
A7: Site Superintendent | B7: Nicholas Scarmacca
A8: Assistant Project Manager | B8: Hugh McDonagh
A9: Director of Construction | B9: Enda Forrey
A11: B. QA/QC ACTIVITY & GOVERNANCE MATRIX
A12: Type | B12: Requirement | C12: Tool / Format | D12: Sign-Off | E12: Stored Where
A13: First Delivery Inspection | B13: HVAC equipment (RT-1, PDU-1, ERV-1/2, AC-1 to AC-5) Switchgear & panels (SWBD-1, MP-1, KP-1, LP-1, RP-1) Rheem tankless water heaters + ST-120 tank Waterproofing membrane system Tile & stone (TL-1, TL-2, TL-3) Millwork & casework Doors, frames & hardware Sprinkler heads (87) Fire alarm devices (FACP / RAN) ACT ceiling panels & grid Plumbing fixtures (incl. Kohler substitution) Lighting fixtures & controls Glass block Wood flooring | C13: Procore Inspection Checklist | D13: Superintendent / Trade Partner | E13: Procore — Inspections
A14: Benchmark Inspection | B14: Wet-area waterproofing (locker rooms, showers, pool deck) Waterproofing interface at Owner's pool / sauna assemblies Pool equipment room slab & CIP concrete Metal stud framing (barrel vault, soffits) GWB Level 5 skim finish Tile & stone (each type) Polished / sealed concrete at BOH Firestopping (typical rated penetration) Millwork (locker unit, reception desk) Doors & hardware Painting & wall coverings ACT ceiling grid MEP rough-in (pre-cover) Above-ceiling close-up | C14: Procore Inspection + Benchmark Form | D14: Q-Team / Trade Partner | E14: Procore — Benchmarks / PDF binder
A15: Mock-Up Review | B15: Tile & stone — pool deck / shower assembly with waterproofing transition GWB Level 5 skim finish panel Locker unit & reception desk first article Polished / sealed concrete floor sample (BOH) Paint & wall covering sample area Glass block wall panel Firestopping typical UL penetration Wood flooring accent panel (pool / lounge) | C15: In-field physical sample + photo log | D15: Q-Team / Architect / Client Rep | E15: Onsite + Procore Photo Documentation
A16: Non-Conformance Report (NCR) | B16: Documented deviation from plans/specs or unacceptable workmanship | C16: Procore Observations Tool | D16: Superintendent / PM | E16: Procore — Observations
A17: Control Samples | B17: Keep one sample of each approved material onsite | C17: Stored physically in labeled plastic box | D17: QA/QC Manager | E17: Site Office Sample Bin
A18: Punchlist Walks | B18: Final completion walkthrough for trade and general scopes | C18: Procore Punchlist Tool | D18: Q-Team / Design Team / Client Rep | E18: Procore — Punchlists
A19: Monthly QA Review | B19: Review completed vs. missed benchmarks | C19: Internal Project Schedule / QA Log | D19: PM / Superintendent | E19: Project Folder / QA Dashboard

Sheet DFOW Risk Register
A1: SAUNALOUNGE — DFOW RISK & QUALITY GOVERNANCE MATRIX (Playbook App. D-B)
A2: 45 South 3rd Street, Ground Floor, Brooklyn NY 11249 | Affect Build, LLC | Tier drives inspection intensity, documentation level and Q-Team attendance
A4: DFOW ID | B4: DFOW / Definable Feature of Work | C4: Tier | D4: Risk Level | E4: Insp. Intensity / Follow-Up Freq. | F4: CSI Div / Spec | G4: Zone / Location | H4: Responsible Trade Partner | I4: Affect Lead (PM / Super) | J4: Mock-Up Req'd | K4: Hold / Witness Points | L4: Special Insp. Req'd (TR) | M4: Ph.1 Preparatory | N4: Ph.2 Work Readiness | O4: Ph.3 First Work Review | P4: Ph.4 Follow-Up Status | Q4: Notes
A5: D-01 | B5: Wet-area waterproofing — pool deck, locker rooms, showers, kitchen | C5: 4 | D5: =IF($C5=4,"Critical",IF($C5=3,"High",IF($C5=2,"Moderate",IF($C5=1,"Low","")))) -> Critical | E5: =IF($C5=4,"Daily follow-up; dual sign-off; QA/QC Mgr at all hold points",IF($C5=3,"Every-other-day follow-up; A/E at First Work Review",IF($C5=2,"Weekly follow-up; Superintendent-led",IF($C5=1,"At completion; Superintendent spot-check","")))) -> Daily follow-up; dual sign-off; QA/QC Mgr at all hold points | F5: 39879 | G5: Zone A & B wet areas | I5: N. Scarmacca (Super) | J5: Yes | K5: HOLD — before tile/topping cover-up | L5: TR12/13-adjacent
A6: D-02 | B6: Waterproofing interface w/ Owner's pool shell, sauna & cold plunge assemblies | C6: 4 | D6: =IF($C6=4,"Critical",IF($C6=3,"High",IF($C6=2,"Moderate",IF($C6=1,"Low","")))) -> Critical | E6: =IF($C6=4,"Daily follow-up; dual sign-off; QA/QC Mgr at all hold points",IF($C6=3,"Every-other-day follow-up; A/E at First Work Review",IF($C6=2,"Weekly follow-up; Superintendent-led",IF($C6=1,"At completion; Superintendent spot-check","")))) -> Daily follow-up; dual sign-off; QA/QC Mgr at all hold points | F6: 7 | G6: Pool room (Zone B) | I6: N. Scarmacca (Super) / I. Aguire (PM) | J6: Yes | K6: HOLD — joint interface inspection w/ Owner vendor | L6: TR12/13-adjacent
A7: D-03 | B7: Fire Alarm system — FACP, RAN, initiating / notification devices | C7: 4 | D7: =IF($C7=4,"Critical",IF($C7=3,"High",IF($C7=2,"Moderate",IF($C7=1,"Low","")))) -> Critical | E7: =IF($C7=4,"Daily follow-up; dual sign-off; QA/QC Mgr at all hold points",IF($C7=3,"Every-other-day follow-up; A/E at First Work Review",IF($C7=2,"Weekly follow-up; Superintendent-led",IF($C7=1,"At completion; Superintendent spot-check","")))) -> Daily follow-up; dual sign-off; QA/QC Mgr at all hold points | F7: 28 31 00 | G7: Whole premises | I7: I. Aguire (PM) | J7: No | K7: HOLD — 100% device pre-test; WITNESS — FDNY acceptance | L7: TR1
A8: D-04 | B8: Fire Sprinkler & standpipe — 87 new heads, main & branch | C8: 4 | D8: =IF($C8=4,"Critical",IF($C8=3,"High",IF($C8=2,"Moderate",IF($C8=1,"Low","")))) -> Critical | E8: =IF($C8=4,"Daily follow-up; dual sign-off; QA/QC Mgr at all hold points",IF($C8=3,"Every-other-day follow-up; A/E at First Work Review",IF($C8=2,"Weekly follow-up; Superintendent-led",IF($C8=1,"At completion; Superintendent spot-check","")))) -> Daily follow-up; dual sign-off; QA/QC Mgr at all hold points | F8: 21 13 00 | G8: Whole premises | I8: N. Scarmacca (Super) | J8: No | K8: HOLD — hydrostatic 200 psi / 2 hr (DOB witness); WITNESS — FDNY flow test | L8: TR1
A9: D-05 | B9: Electrical service, switchgear & panels MP-1, KP-1, LP-1, RP-1, SWBD-1 | C9: 4 | D9: =IF($C9=4,"Critical",IF($C9=3,"High",IF($C9=2,"Moderate",IF($C9=1,"Low","")))) -> Critical | E9: =IF($C9=4,"Daily follow-up; dual sign-off; QA/QC Mgr at all hold points",IF($C9=3,"Every-other-day follow-up; A/E at First Work Review",IF($C9=2,"Weekly follow-up; Superintendent-led",IF($C9=1,"At completion; Superintendent spot-check","")))) -> Daily follow-up; dual sign-off; QA/QC Mgr at all hold points | F9: 26 20 00 | G9: Elec. room / Zones A & B | I9: I. Aguire (PM) | J9: No | K9: HOLD — pre-energisation inspection & megger | L9: TR - Electrical
A10: D-06 | B10: Gas piping & elevated-pressure gas service connection | C10: 4 | D10: =IF($C10=4,"Critical",IF($C10=3,"High",IF($C10=2,"Moderate",IF($C10=1,"Low","")))) -> Critical | E10: =IF($C10=4,"Daily follow-up; dual sign-off; QA/QC Mgr at all hold points",IF($C10=3,"Every-other-day follow-up; A/E at First Work Review",IF($C10=2,"Weekly follow-up; Superintendent-led",IF($C10=1,"At completion; Superintendent spot-check","")))) -> Daily follow-up; dual sign-off; QA/QC Mgr at all hold points | F10: 22 11 00 | G10: Kitchen / mech. | I10: N. Scarmacca (Super) | J10: No | K10: HOLD — 10 psi / 15 min pressure test (DOB witness) | L10: DOB Plumbing
A11: D-07 | B11: Pool equipment room slab & CIP concrete | C11: 3 | D11: =IF($C11=4,"Critical",IF($C11=3,"High",IF($C11=2,"Moderate",IF($C11=1,"Low","")))) -> High | E11: =IF($C11=4,"Daily follow-up; dual sign-off; QA/QC Mgr at all hold points",IF($C11=3,"Every-other-day follow-up; A/E at First Work Review",IF($C11=2,"Weekly follow-up; Superintendent-led",IF($C11=1,"At completion; Superintendent spot-check","")))) -> Every-other-day follow-up; A/E at First Work Review | F11: 03 30 00 | G11: Pool equipment room | I11: N. Scarmacca (Super) | J11: No | K11: HOLD — pre-pour rebar/embeds; WITNESS — each pour | L11: TR2 / TR3
A12: D-08 | B12: Excavation & support of excavation — pool equipment room (150 CY) | C12: 3 | D12: =IF($C12=4,"Critical",IF($C12=3,"High",IF($C12=2,"Moderate",IF($C12=1,"Low","")))) -> High | E12: =IF($C12=4,"Daily follow-up; dual sign-off; QA/QC Mgr at all hold points",IF($C12=3,"Every-other-day follow-up; A/E at First Work Review",IF($C12=2,"Weekly follow-up; Superintendent-led",IF($C12=1,"At completion; Superintendent spot-check","")))) -> Every-other-day follow-up; A/E at First Work Review | F12: 31 20 00 | G12: Pool equipment room | I12: N. Scarmacca (Super) | J12: No | K12: HOLD — SOE verification before excavation | L12: TR4 / TR5
A13: D-09 | B13: Domestic hot water — 4x Rheem tankless + ST-120 storage tank | C13: 3 | D13: =IF($C13=4,"Critical",IF($C13=3,"High",IF($C13=2,"Moderate",IF($C13=1,"Low","")))) -> High | E13: =IF($C13=4,"Daily follow-up; dual sign-off; QA/QC Mgr at all hold points",IF($C13=3,"Every-other-day follow-up; A/E at First Work Review",IF($C13=2,"Weekly follow-up; Superintendent-led",IF($C13=1,"At completion; Superintendent spot-check","")))) -> Every-other-day follow-up; A/E at First Work Review | F13: 22 33 00 | G13: Mech. room | I13: I. Aguire (PM) | J13: No | K13: HOLD — combustion test before DOB Boiler Unit insp. | L13: DOB Boiler
A14: D-10 | B14: HVAC equipment — RT-1, PDU-1, ERV-1/2, AC-1 to AC-5, MUA-1, KEF-1 | C14: 3 | D14: =IF($C14=4,"Critical",IF($C14=3,"High",IF($C14=2,"Moderate",IF($C14=1,"Low","")))) -> High | E14: =IF($C14=4,"Daily follow-up; dual sign-off; QA/QC Mgr at all hold points",IF($C14=3,"Every-other-day follow-up; A/E at First Work Review",IF($C14=2,"Weekly follow-up; Superintendent-led",IF($C14=1,"At completion; Superintendent spot-check","")))) -> Every-other-day follow-up; A/E at First Work Review | F14: 23 00 00 | G14: Roof / Zones A & B | I14: I. Aguire (PM) | J14: No | K14: WITNESS — startup & functional performance test | L14: TR8
A15: D-11 | B15: Ductwork Zones A & B incl. duct pressure testing | C15: 3 | D15: =IF($C15=4,"Critical",IF($C15=3,"High",IF($C15=2,"Moderate",IF($C15=1,"Low","")))) -> High | E15: =IF($C15=4,"Daily follow-up; dual sign-off; QA/QC Mgr at all hold points",IF($C15=3,"Every-other-day follow-up; A/E at First Work Review",IF($C15=2,"Weekly follow-up; Superintendent-led",IF($C15=1,"At completion; Superintendent spot-check","")))) -> Every-other-day follow-up; A/E at First Work Review | F15: 23 31 00 | G15: Zones A & B | I15: N. Scarmacca (Super) | J15: No | K15: HOLD — duct pressure test before ceiling close-up | L15: TR8
A16: D-12 | B16: Refrigerant piping — ACCU-1 / ACCU-2 reconnect, ACCU-3 new | C16: 3 | D16: =IF($C16=4,"Critical",IF($C16=3,"High",IF($C16=2,"Moderate",IF($C16=1,"Low","")))) -> High | E16: =IF($C16=4,"Daily follow-up; dual sign-off; QA/QC Mgr at all hold points",IF($C16=3,"Every-other-day follow-up; A/E at First Work Review",IF($C16=2,"Weekly follow-up; Superintendent-led",IF($C16=1,"At completion; Superintendent spot-check","")))) -> Every-other-day follow-up; A/E at First Work Review | F16: 23 23 00 | G16: Roof / Zone A | I16: I. Aguire (PM) | J16: No | K16: HOLD — pressure/vacuum test before charge | L16: —
A17: D-13 | B17: Plumbing rough-in — CW / HW / sanitary / waste / vent | C17: 3 | D17: =IF($C17=4,"Critical",IF($C17=3,"High",IF($C17=2,"Moderate",IF($C17=1,"Low","")))) -> High | E17: =IF($C17=4,"Daily follow-up; dual sign-off; QA/QC Mgr at all hold points",IF($C17=3,"Every-other-day follow-up; A/E at First Work Review",IF($C17=2,"Weekly follow-up; Superintendent-led",IF($C17=1,"At completion; Superintendent spot-check","")))) -> Every-other-day follow-up; A/E at First Work Review | F17: 22 10 00 | G17: Zones A & B | I17: N. Scarmacca (Super) | J17: No | K17: HOLD — pre-cover inspection before GWB | L17: DOB Plumbing
A18: D-14 | B18: Tile & stone — pool floors, locker/shower, lounge/bar, kitchen, ADA restroom | C18: 3 | D18: =IF($C18=4,"Critical",IF($C18=3,"High",IF($C18=2,"Moderate",IF($C18=1,"Low","")))) -> High | E18: =IF($C18=4,"Daily follow-up; dual sign-off; QA/QC Mgr at all hold points",IF($C18=3,"Every-other-day follow-up; A/E at First Work Review",IF($C18=2,"Weekly follow-up; Superintendent-led",IF($C18=1,"At completion; Superintendent spot-check","")))) -> Every-other-day follow-up; A/E at First Work Review | F18: 09 30 00 | G18: Zones A & B | I18: N. Scarmacca (Super) | J18: Yes | K18: HOLD — mock-up sign-off before production | L18: —
... A36: D-32 | B36: Final clean & protection removal | C36: 1 | D36: =IF($C36=4,"Critical",IF($C36=3,"High",IF($C36=2,"Moderate",IF($C36=1,"Low","")))) -> Low | E36: =IF($C36=4,"Daily follow-up; dual sign-off; QA/QC Mgr at all hold points",IF($C36=3,"Every-other-day follow-up; A/E at First Work Review",IF($C36=2,"Weekly follow-up; Superintendent-led",IF($C36=1,"At completion; Superintendent spot-check","")))) -> At completion; Superintendent spot-check | F36: 01 74 00 | G36: Whole premises | I36: N. Scarmacca (Super) | J36: No | K36: At completion | L36: —

Sheet ITP
A1: SAUNALOUNGE — INSPECTION & TESTING PLAN (ITP) | Playbook App. D-C
A2: H = HOLD POINT: work must stop; inspection signed off before proceeding — no exceptions. W = WITNESS POINT: Affect Build and/or A/E notified min. 48 hrs in advance; work may proceed if witness does not attend after proper written notice. All reports uploaded to Procore within 24 hrs of receipt.
A4: ITP ID | B4: DFOW Ref | C4: Test / Inspection Activity | D4: Spec / Code Requirement | E4: Test Method / Standard | F4: Acceptance Criteria | G4: Frequency | H4: Responsible Party | I4: H / W | J4: Notice Req'd | K4: Date Performed | L4: Result | M4: Report Ref (Procore) | N4: Status | O4: Report Distribution
A5: T-01 | B5: D-07 | C5: Concrete compressive strength — pool equipment room slab | D5: NYC BC Ch.17 / TR2-TR3 | E5: ASTM C39 cylinder breaks | F5: Meets design f'c at 28 days | G5: Each pour (min. 1 set per 50 CY) | H5: Licensed Testing Laboratory | I5: H | J5: 48 hrs | O5: PM, Super, SIA, Architect, Collectif
A6: T-02 | B6: D-07 | C6: Concrete slump, air content & temperature | D6: NYC BC Ch.17 / TR2 | E6: ASTM C143 / C231 / C1064 | F6: Within approved mix design tolerances | G6: Each truck / each pour | H6: Licensed Testing Laboratory | I6: W | J6: 48 hrs | O6: PM, Super, SIA
A7: T-03 | B7: D-07 | C7: Pre-pour rebar, embeds & formwork verification | D7: Structural drawings / TR3 | E7: Visual + tape measure vs. shop drawings | F7: Placement, cover and laps per approved shops | G7: Before every pour | H7: Special Inspection Agency | I7: H | J7: 48 hrs | O7: PM, Super, SIA, Architect
A8: T-04 | B8: D-08 | C8: Excavation / SOE verification — pool equipment room | D8: NYC BC Ch.33 / TR4-TR5 | E8: Survey + visual vs. approved SOE drawings | F8: Sloped excavation per approved SOE; no undermining | G8: Before and during excavation | H8: Special Inspection Agency | I8: H | J8: 48 hrs | O8: PM, Super, SIA
A9: T-05 | B9: D-01 | C9: Wet-area waterproofing flood test — locker rooms, showers, pool deck | D9: Manufacturer's requirements / 07 | E9: Flood test min. 24 hrs, 2 in. head | F9: No loss of head; no evidence of leakage | G9: Each wet area, before cover-up | H9: Waterproofing Subcontractor | I9: H | J9: 48 hrs | O9: PM, Super, Architect, Owner
A10: T-06 | B10: D-02 | C10: Interface inspection — Affect waterproofing to Owner's pool / sauna assemblies | D10: Contract §12.4 / manufacturer | E10: Joint visual inspection + photo record | F10: Continuous termination; no gaps at transition | G10: At each interface, before cover-up | H10: N. Scarmacca (Super) + Owner's Pool Vendor | I10: H | J10: 72 hrs | O10: PM, Super, Architect, Owner's Vendor
A11: T-07 | B11: D-17 | C11: Roof flood / water test at RTU-1 curbs and penetrations | D11: 07 50 00 / manufacturer | E11: Water test / spray test | F11: No leakage at curbs, flashings or penetrations | G11: Once, after flashing complete | H11: Roofing Subcontractor | I11: H | J11: 48 hrs | O11: PM, Super, Architect
A12: T-08 | B12: D-04 | C12: Sprinkler hydrostatic test | D12: NFPA 13 / NYC BC / TR1 | E12: Hydrostatic pressure test | F12: 200 psi held 2 hrs with no loss | G12: Once per system, all new piping | H12: Sprinkler Subcontractor (DOB witness) | I12: H | J12: 72 hrs | O12: PM, Super, DOB, FDNY, SIA
A13: T-09 | B13: D-04 | C13: Sprinkler flow test — waterflow & tamper switches | D13: NFPA 13 / FDNY | E13: Flow test at inspector's test connection | F13: Alarm signal within 90 sec; correct pressure | G13: Once, at final acceptance | H13: Sprinkler Subcontractor (FDNY witness) | I13: W | J13: 72 hrs | O13: PM, Super, FDNY, SIA
A14: T-10 | B14: D-03 | C14: Fire alarm 100% device pre-test | D14: NFPA 72 / FDNY / TR1 | E14: Point-by-point functional device test | F14: 100% of initiating, signaling & notification devices operate | G14: Once, before FDNY witness test | H14: Fire Alarm Subcontractor | I14: H | J14: 72 hrs | O14: PM, Super, Collectif, SIA
A15: T-11 | B15: D-03 | C15: Fire alarm interface test — HVAC damper closure & door hold-open release | D15: NFPA 72 / NYC MC | E15: Functional interface test | F15: All dampers close and hold-opens release on alarm | G15: Once, with pre-test | H15: Fire Alarm + Mechanical Subs | I15: H | J15: 72 hrs | O15: PM, Super, Collectif
A16: T-12 | B16: D-03 | C16: FDNY fire alarm witness / acceptance test | D16: FDNY rules / TR1 | E16: FDNY witnessed live device test | F16: FDNY Letter of Approval (LOA) issued | G16: Once (≥2 weeks before 12/21/26) | H16: FDNY Inspector | I16: W | J16: 2 weeks | O16: PM, Super, Owner, FDNY, SIA
... A35: T-31 | B35: — | C35: DOH Pool / Spa final inspection (Owner's Separate Trades) | D35: NYC DOH / Contract §12.4 | E35: DOH inspector site inspection | F35: DOH Pool/Spa approval issued | G35: Once, before occupancy | H35: NYC DOH / Owner's Pool Vendor | I35: H | J35: 2 weeks | O35: PM, Super, Owner, DOH

Sheet Path to TCO
A1: SAUNALOUNGE — PATH TO TCO | Statutory Sign-Off Gate Register
A2: TCO Request is filed via DOB NOW only once ALL of the following are complete: FDNY Fire Alarm LOA · Sprinkler/Standpipe approval · Electrical & Plumbing final certificates · DOH Pool/Spa approval · all Special Inspection (TR) closures. (CMP §20.4)
A4: Target Substantial Completion | C4: =DATE(2026,12,21) -> 46377 | D4: Total Gates | E4: =COUNTA($A$9:$A$71) -> 46 | F4: Complete | G4: =COUNTIF($I$9:$I$71,"Complete") -> 0 | H4: Outstanding | I4: =$E$4-$G$4 -> 46 | J4: TCO Readiness | K4: =IF($E$4=0,0,$G$4/$E$4) -> 0
A8: Step | B8: Gate / Milestone | C8: Category | D8: Agency / Authority | E8: Prerequisite Step(s) | F8: Responsible | G8: Required Document / Certificate | H8: Target Date | I8: Status | J8: Actual Date | K8: Days to SC | L8: Procore / DOB NOW Ref | M8: Notes
B9: A. PERMITS, FILINGS & PRECONSTRUCTION | K9: =IF(OR($A9="SECTION",$H9=""),"",$C$4-$H9)
A10: A1 | B10: PW1 / PW2 filings approved and work permits issued | C10: DOB | D10: NYC DOB | E10: — | F10: I. Aguire (PM) | G10: Approved PW1, issued PW2 work permit | I10: Not Started | K10: =IF(OR($A10="SECTION",$H10=""),"",$C$4-$H10)
A11: A2 | B11: TR1 (Technical Report — Statement of Responsibility) filed and accepted | C11: DOB | D11: NYC DOB / SIA | E11: A1 | F11: I. Aguire (PM) | G11: Accepted TR1 in DOB NOW | I11: Not Started | K11: =IF(OR($A11="SECTION",$H11=""),"",$C$4-$H11)
A12: A3 | B12: TR8 (Energy / Mechanical) filed and accepted | C12: DOB | D12: NYC DOB / Collectif | E12: A1 | F12: I. Aguire (PM) | G12: Accepted TR8 in DOB NOW | I12: Not Started | K12: =IF(OR($A12="SECTION",$H12=""),"",$C$4-$H12)
A13: A4 | B13: Special Inspection Agency and Testing Laboratory engaged and on record | C13: Internal | D13: Affect Build | E13: A2 | F13: I. Aguire (PM) | G13: Executed agency agreements | I13: Not Started | K13: =IF(OR($A13="SECTION",$H13=""),"",$C$4-$H13)
A14: A5 | B14: Physical inspector sign-in logbook established at site entry | C14: Internal | D14: Affect Build | E14: A1 | F14: N. Scarmacca (Super) | G14: Bound logbook on site (see Inspector Sign-In tab) | I14: Not Started | K14: =IF(OR($A14="SECTION",$H14=""),"",$C$4-$H14)
A15: A6 | B15: Permit board, site safety and code postings in place | C15: DOB | D15: NYC DOB | E15: A1 | F15: N. Scarmacca (Super) | G15: Photo record of postings | I15: Not Started | K15: =IF(OR($A15="SECTION",$H15=""),"",$C$4-$H15)
A16: A7 | B16: CodeGreen (CGI) Preliminary special inspection completed | C16: Special Insp. | D16: CodeGreen Inspection (CGI) | E16: A1,A4 | F16: N. Scarmacca (Super) | G16: CGI Preliminary inspection report | I16: Not Started | K16: =IF(OR($A16="SECTION",$H16=""),"",$C$4-$H16) | M16: MUST occur PRIOR TO any work being performed on site (CGI matrix 2026-0401). Allow min. 2-3 days to schedule
B17: B. SPECIAL INSPECTION (TR) CLOSURES — CMP §12.6 | K17: =IF(OR($A17="SECTION",$H17=""),"",$C$4-$H17)
A18: B1 | B18: Concrete placement special inspections complete — pool equipment room slab | C18: Special Insp. | D18: Licensed Testing Lab | E18: A2 | F18: N. Scarmacca (Super) | G18: Signed TR2 / TR3 reports, all pours | I18: Not Started | K18: =IF(OR($A18="SECTION",$H18=""),"",$C$4-$H18)
A19: B2 | B19: Excavation / SOE special inspections complete | C19: Special Insp. | D19: Special Inspection Agency | E19: A2 | F19: N. Scarmacca (Super) | G19: Signed TR reports | I19: Not Started | K19: =IF(OR($A19="SECTION",$H19=""),"",$C$4-$H19)
A20: B3 | B20: Waterproofing (wet-area interface) special inspections complete | C20: Special Insp. | D20: Independent Inspector | E20: A2 | F20: N. Scarmacca (Super) | G20: Signed inspection reports, all wet areas | I20: Not Started | K20: =IF(OR($A20="SECTION",$H20=""),"",$C$4-$H20)
A21: B4 | B21: Firestopping special inspections complete — all rated penetrations | C21: Special Insp. | D21: Special Inspection Agency | E21: A2 | F21: N. Scarmacca (Super) | G21: Signed inspection reports | I21: Not Started | K21: =IF(OR($A21="SECTION",$H21=""),"",$C$4-$H21)
A22: B5 | B22: Mechanical / Energy Code compliance special inspection signed off | C22: Special Insp. | D22: Collectif (Mech. Engineer) | E22: A3 | F22: I. Aguire (PM) | G22: Signed TR8 | I22: Not Started | K22: =IF(OR($A22="SECTION",$H22=""),"",$C$4-$H22)
A23: B6 | B23: Sprinkler / Fire Alarm special inspection signed off | C23: Special Insp. | D23: Approved Inspector | E23: A2 | F23: I. Aguire (PM) | G23: Signed TR1 for FA / sprinkler | I23: Not Started | K23: =IF(OR($A23="SECTION",$H23=""),"",$C$4-$H23)
A24: B7 | B24: FINAL TR1 sign-off letter received from Special Inspection Agency | C24: Special Insp. | D24: Special Inspection Agency | E24: B1,B2,B3,B4,B5,B6 | F24: I. Aguire (PM) | G24: Final TR1 Sign-Off Letter (mandatory TCO prerequisite) | I24: Not Started | K24: =IF(OR($A24="SECTION",$H24=""),"",$C$4-$H24)
B25: C. LIFE SAFETY SIGN-OFFS | K25: =IF(OR($A25="SECTION",$H25=""),"",$C$4-$H25)
A26: C1 | B26: Fire alarm 100% device pre-test complete (see Path to Fire Alarm tab) | C26: FDNY | D26: Fire Alarm Sub | E26: A1 | F26: I. Aguire (PM) | G26: Signed 100% device pre-test report | I26: Not Started | K26: =IF(OR($A26="SECTION",$H26=""),"",$C$4-$H26)
A27: C2 | B27: FDNY witness / acceptance test passed — Letter of Approval issued | C27: FDNY | D27: FDNY | E27: C1 | F27: I. Aguire (PM) | G27: FDNY Letter of Approval (LOA) | I27: Not Started | K27: =IF(OR($A27="SECTION",$H27=""),"",$C$4-$H27)
A28: C3 | B28: Sprinkler hydrostatic test passed — 200 psi / 2 hrs, DOB witnessed | C28: DOB | D28: NYC DOB | E28: A1 | F28: N. Scarmacca (Super) | G28: Signed hydrostatic test record | I28: Not Started | K28: =IF(OR($A28="SECTION",$H28=""),"",$C$4-$H28)
A29: C4 | B29: Sprinkler flow test / FDNY field acceptance — waterflow & tamper switches | C29: FDNY | D29: FDNY | E29: C3 | F29: N. Scarmacca (Super) | G29: FDNY field acceptance record | I29: Not Started | K29: =IF(OR($A29="SECTION",$H29=""),"",$C$4-$H29)
A30: C5 | B30: Central station alarm transmission verified | C30: FDNY | D30: FDNY / Central Station | E30: C2 | F30: I. Aguire (PM) | G30: Central station verification letter | I30: Not Started | K30: =IF(OR($A30="SECTION",$H30=""),"",$C$4-$H30)
B31: D. UTILITY & AGENCY SIGN-OFFS — CMP §19.3 / §20.2 | K31: =IF(OR($A31="SECTION",$H31=""),"",$C$4-$H31)
A32: D1 | B32: Electrical rough inspection passed | C32: DOB | D32: DOB Electrical | E32: A1 | F32: I. Aguire (PM) | G32: Rough inspection record | I32: Not Started | K32: =IF(OR($A32="SECTION",$H32=""),"",$C$4-$H32)
A33: D2 | B33: Electrical final inspection — Certificate of Electrical Inspection issued | C33: DOB | D33: DOB Electrical | E33: D1 | F33: I. Aguire (PM) | G33: Certificate of Electrical Inspection (or DOB NOW self-cert) | I33: Not Started | K33: =IF(OR($A33="SECTION",$H33=""),"",$C$4-$H33)
A34: D3 | B34: Con Edison energisation letter received | C34: Utility | D34: Con Edison | E34: D2 | F34: I. Aguire (PM) | G34: Energisation letter | I34: Not Started | K34: =IF(OR($A34="SECTION",$H34=""),"",$C$4-$H34)
A35: D4 | B35: Plumbing rough inspection passed (water / sanitary / vent) | C35: DOB | D35: DOB Plumbing | E35: A1 | F35: N. Scarmacca (Super) | G35: Rough inspection sign-off | I35: Not Started | K35: =IF(OR($A35="SECTION",$H35=""),"",$C$4-$H35)
A36: D5 | B36: Gas pressure test passed — 10 psi / 15 min, DOB witnessed | C36: DOB | D36: DOB Plumbing | E36: D4 | F36: N. Scarmacca (Super) | G36: Signed gas pressure test record | I36: Not Started | K36: =IF(OR($A36="SECTION",$H36=""),"",$C$4-$H36)
A37: D6 | B37: Gas Activation Notice received | C37: Utility | D37: Con Edison / National Grid | E37: D5 | F37: I. Aguire (PM) | G37: Gas Activation Notice | I37: Not Started | K37: =IF(OR($A37="SECTION",$H37=""),"",$C$4-$H37)
A38: D7 | B38: DOB Boiler Unit inspection — after Rheem water heater combustion testing | C38: DOB | D38: DOB Boiler Unit | E38: D6 | F38: I. Aguire (PM) | G38: Boiler inspection sign-off | I38: Not Started | K38: =IF(OR($A38="SECTION",$H38=""),"",$C$4-$H38)
A39: D8 | B39: Plumbing final inspection / sign-off | C39: DOB | D39: DOB Plumbing | E39: D5 | F39: N. Scarmacca (Super) | G39: Plumbing final sign-off | I39: Not Started | K39: =IF(OR($A39="SECTION",$H39=""),"",$C$4-$H39)
A40: D9 | B40: DEP water meter set | C40: DEP | D40: NYC DEP | E40: A1 | F40: I. Aguire (PM) | G40: Meter set confirmation | I40: Not Started | K40: =IF(OR($A40="SECTION",$H40=""),"",$C$4-$H40)
A41: D10 | B41: DEP backflow prevention certification filed | C41: DEP | D41: NYC DEP | E41: D9 | F41: I. Aguire (PM) | G41: Backflow certification | I41: Not Started | K41: =IF(OR($A41="SECTION",$H41=""),"",$C$4-$H41)
A42: D11 | B42: DEP final sewer connection approval | C42: DEP | D42: NYC DEP | E42: A1 | F42: I. Aguire (PM) | G42: Sewer connection approval | I42: Not Started | K42: =IF(OR($A42="SECTION",$H42=""),"",$C$4-$H42)
B43: E. DOH POOL / SPA — OWNER'S SEPARATE TRADES (CMP §20.3) | K43: =IF(OR($A43="SECTION",$H43=""),"",$C$4-$H43)
A44: E1 | B44: Pool / sauna / cold plunge utility readiness confirmed (electrical, plumbing, trenching) | C44: Internal | D44: Affect Build | E44: D2,D8 | F44: N. Scarmacca (Super) | G44: Utility readiness sign-off | I44: Not Started | K44: =IF(OR($A44="SECTION",$H44=""),"",$C$4-$H44)
...

Sheet Path to Fire Alarm
A1: SAUNALOUNGE — PATH TO FIRE ALARM SIGN-OFF (FDNY LETTER OF APPROVAL)
A2: The FDNY Letter of Approval (LOA) is a MANDATORY prerequisite for TCO/CO. Per CMP §20.1, FDNY witness testing must be scheduled at least two weeks before the anticipated Substantial Completion date to allow for re-tests.
A4: Substantial Completion Target | D4: =DATE(2026,12,21) -> 46377 | E4: Latest FDNY Test Date (SC − 14 days) | H4: =$D$4-14 -> 46363 | I4: Steps Complete | K4: =COUNTIF($H$8:$H$40,"Complete")&" / "&COUNTA($A$8:$A$40) -> 0 / 23
A7: Step | B7: Activity / Gate | C7: Responsible Party | D7: Predecessor | E7: Advance Notice Req'd | F7: Target Date | G7: Actual Date | H7: Status | I7: Evidence / Document Required | J7: Notes
A8: FA-01 | B8: Fire alarm shop drawings and device layout submitted to Collectif and Architect for review | C8: Fire Alarm Sub | D8: — | E8: — | H8: Not Started | I8: Approved shop drawings (Procore submittal)
A9: FA-02 | B9: Fire alarm drawings filed with FDNY / DOB as required; approval obtained | C9: I. Aguire (PM) | D9: FA-01 | E9: 4–6 weeks | H9: Not Started | I9: FDNY / DOB drawing approval
A10: FA-03 | B10: FACP, RAN and device rough-in complete — Zones A & B | C10: Fire Alarm Sub | D10: FA-02 | E10: — | H10: Not Started | I10: Pre-cover inspection sign-off
A11: FA-04 | B11: Pre-cover (pre-drywall) inspection of FA rough-in — HOLD POINT | C11: N. Scarmacca (Super) | D11: FA-03 | E11: 48 hrs | H11: Not Started | I11: Signed pre-cover inspection record (Procore)
A12: FA-05 | B12: Device trim-out complete — initiating, signaling and notification devices installed | C12: Fire Alarm Sub | D12: FA-04 | E12: — | H12: Not Started | I12: Device installation checklist
A13: FA-06 | B13: Above-ceiling inspection before ACT / grid close-up — HOLD POINT | C13: N. Scarmacca (Super) | D13: FA-05 | E13: 48 hrs | H13: Not Started | I13: Above-ceiling inspection record
A14: FA-07 | B14: Permanent electrical power available to FACP (energisation sequenced ahead of FA testing) | C14: Electrical Sub | D14: — | E14: — | H14: Not Started | I14: Con Edison energisation letter / panel energised
A15: FA-08 | B15: Device labelling, zone schedule and as-built riser diagram complete | C15: Fire Alarm Sub | D15: FA-05 | E15: — | H15: Not Started | I15: As-built riser + zone schedule
A16: FA-09 | B16: 100% pre-test of ALL initiating, signaling and notification devices — HOLD POINT | C16: Fire Alarm Sub | D16: FA-05,FA-07 | E16: 72 hrs | H16: Not Started | I16: Signed 100% device pre-test report
A17: FA-10 | B17: Interface test — HVAC damper closure on alarm verified | C17: Fire Alarm + Mechanical Subs | D17: FA-09 | E17: 72 hrs | H17: Not Started | I17: Signed interface test record
A18: FA-11 | B18: Interface test — door hold-open device release on alarm verified | C18: Fire Alarm + Door Hardware Sub | D18: FA-09 | E18: 72 hrs | H18: Not Started | I18: Signed interface test record
A19: FA-12 | B19: Interface test — sprinkler waterflow and tamper switch supervision to FACP verified | C19: Fire Alarm + Sprinkler Subs | D19: FA-09 | E19: 72 hrs | H19: Not Started | I19: Signed interface test record
... A30: FA-23 | B30: Fire alarm O&M manual, warranty and as-builts turned over | C30: Fire Alarm Sub | D30: FA-20 | E30: — | H30: Not Started | I30: O&M manual + warranty letter

Sheet DOH Checklist
A1: SAUNALOUNGE — NYC DEPARTMENT OF HEALTH (DOHMH) COMPLIANCE CHECKLIST | FIRST PASS
A2: FIRST PASS — awareness and coordination checklist, NOT a code compliance certification. Pool, sauna and cold plunge are Owner's Separate Trades under Contract §12.4: furnished, installed, tested and commissioned by the Owner's vendors. Affect Build coordinates access, utility readiness and scheduling, and is NOT responsible for design or performance certification of these systems. EVERY numeric criterion and code citation below must be confirmed by the Owner's DOH consultant and the pool designer against NYS Sanitary Code Subpart 6-1, NYC Health Code Article 165 and Article 81 before it is relied upon.
A4: Total Items | B4: =COUNTIF($A$7:$A$130,"H-*") -> 101 | C4: Verified | D4: =COUNTIF($F$7:$F$130,"Verified") -> 0 | E4: Outstanding | F4: =$B$4-$D$4-COUNTIF($F$7:$F$130,"N/A") -> 101 | G4: Affect Build Items | H4: =COUNTIF($C$7:$C$130,"Affect Build")+COUNTIF($C$7:$C$130,"Shared — AB / Owner's Vendor") -> 56 | I4: % Verified | J4: =IF($B$4=0,0,$D$4/$B$4) -> 0
A6: ID | B6: Item / Requirement to Verify | C6: Responsibility | D6: Affect Build Interface / Exposure | E6: Evidence / Document Required | F6: Status | G6: Verified By | H6: Date | I6: Reference to Confirm | J6: Notes
A7: A. PERMITS, PLAN APPROVAL & ADMINISTRATION
A8: H-01 | B8: Pool / spa construction plans submitted to and approved by DOHMH before construction of the pool shell | C8: Owner / DOH Consultant | D8: AB must not build out enclosing finishes until plan approval is confirmed | E8: Stamped approved DOH plan set | I8: NYC Health Code Art. 165 / NYS Subpart 6-1
A9: H-02 | B9: Confirm whether the facility is classified as a swimming pool, spa, or both — classification drives the applicable requirements | C9: Owner / DOH Consultant | D9: Drives ventilation, drainage and finish requirements in AB scope | E9: Written DOH classification determination | I9: Subpart 6-1 definitions
A10: H-03 | B10: DOH Permit to Operate application filed; permit issued prior to public use | C10: Owner / DOH Consultant | D10: Prerequisite to TCO for pool / sauna areas (CMP §20.3) | E10: Issued DOH Permit to Operate | I10: Art. 165
A11: H-04 | B11: Food Service Establishment permit application for kitchen and bar filed with DOHMH | C11: Owner / DOH Consultant | D11: AB builds out kitchen / bar to DOH-acceptable finishes and equipment rough-in | E11: FSE permit application + issued permit | I11: NYC Health Code Art. 81
A12: H-05 | B12: Food service plan review / pre-permit inspection scheduled with DOHMH | C12: Owner / DOH Consultant | D12: AB coordinates access and completion sequencing | E12: Plan review approval letter | I12: Art. 81
A13: H-06 | B13: Owner's DOH consultant engaged and scope of responsibility documented in writing | C13: Owner / DOH Consultant | D13: Clarifies the boundary between AB scope and Owner's vendors | E13: Consultant agreement / scope letter | I13: Contract §12.4
A14: H-07 | B14: Certified Pool Operator (CPO) or equivalent qualified operator identified before opening | C14: Owner's Separate Trades | D14: None — Owner responsibility; note in turnover package | E14: CPO certificate | I14: Subpart 6-1
A15: H-08 | B15: Safety plan / operation & maintenance plan prepared and submitted as required | C15: Owner's Separate Trades | D15: AB provides equipment O&M data to support the plan | E15: Approved safety plan | I15: Subpart 6-1
A16: H-09 | B16: Confirm whether lifeguard supervision is required for this facility, or 'no lifeguard' operation is permitted | C16: Owner / DOH Consultant | D16: Determines required signage that AB may install | E16: Written DOH determination | I16: Subpart 6-1
A17: B. POOL / SPA STRUCTURE, FINISHES & DECK
A18: H-10 | B18: Pool shell structure and interior finish light in colour, smooth, non-toxic, easily cleaned and non-slip where required | C18: Owner's Separate Trades | D18: AB interface at coping / deck transition only | E18: Product data + DOH approval | I18: Subpart 6-1
A19: H-11 | B19: Water depth markings and 'NO DIVING' markings provided at required locations, contrasting and slip-resistant | C19: Owner's Separate Trades | D19: Confirm tile / marking supply responsibility — AB tile scope excludes coping and waterline band | E19: Photo record + approved layout | I19: Subpart 6-1
A20: H-12 | B20: Depth transition / break in slope clearly marked; safety line and anchors provided where required | C20: Owner's Separate Trades | D20: None | E20: Approved layout | I20: Subpart 6-1
A21: H-13 | B21: Steps, ladders, handrails and recessed treads provided, slip-resistant and securely anchored | C21: Owner's Separate Trades | D21: AB verifies anchorage substrate where anchors land in AB-installed work | E21: Installation certification | I21: Subpart 6-1
A22: H-14 | B22: Deck surface slip-resistant, sloped to drain away from the pool, free of standing water | C22: Shared — AB / Owner's Vendor | D22: AB tile / topping scope at pool deck — slope and slip resistance are AB deliverables | E22: Slope survey + COF test data for tile | I22: Subpart 6-1 / TCNA
A23: H-15 | B23: Minimum unobstructed deck width around the pool perimeter maintained | C23: Shared — AB / Owner's Vendor | D23: AB layout and framing must not encroach — verify against approved DOH plan | E23: Dimensioned as-built plan | I23: Subpart 6-1 — VERIFY DIMENSION
A24: H-16 | B24: Deck drainage provided; deck drains do not discharge to the pool recirculation system | C24: Shared — AB / Owner's Vendor | D24: AB plumbing scope — trench / floor drains and slope | E24: Approved plumbing plan + as-built | I24: Subpart 6-1 / NYC PC
A25: H-17 | B25: Coping, waterline contrast band, step / bench nose tile and plaster finish installed by the pool specialist | C25: Owner's Separate Trades | D25: EXPLICITLY EXCLUDED from AB tile scope per Client Summary — confirm no gap in scope | E25: Scope confirmation letter | I25: Client Summary / Contract §12.4
A26: H-18 | B26: No sharp edges, protrusions or entrapment gaps in the pool, spa or plunge basin | C26: Owner's Separate Trades | D26: AB verifies none created by adjacent AB work | E26: Joint inspection record | I26: Subpart 6-1
A27: H-19 | B27: Barrier / enclosure preventing unsupervised access, with self-closing and self-latching gates where required | C27: Shared — AB / Owner's Vendor | D27: AB may install partitions, doors and hardware forming the barrier | E27: Approved barrier detail + hardware submittal | I27: Subpart 6-1 / Art. 165
A28: C. CIRCULATION, FILTRATION & TURNOVER
A29: H-20 | B29: Recirculation system sized to achieve the required turnover rate for each body of water | C29: Owner's Separate Trades | D29: AB provides electrical and plumbing rough-in and equipment room readiness only | E29: Designer's turnover calculation | I29: Subpart 6-1 — VERIFY TURNOVER RATE
A30: H-21 | B30: Filtration system type, rate and media approved; filter gauges and sight glass provided | C30: Owner's Separate Trades | D30: AB equipment room space, drainage and utilities | E30: Equipment submittal + DOH approval | I30: Subpart 6-1
A31: H-22 | B31: Flow meter installed, accessible and readable on the recirculation line | C31: Owner's Separate Trades | D31: AB piping access and lighting in equipment room | E31: Photo record | I31: Subpart 6-1
A32: H-23 | B32: Hair and lint strainer provided ahead of the pump; accessible for cleaning | C32: Owner's Separate Trades | D32: AB clearance and drainage provision | E32: Equipment submittal | I32: Subpart 6-1
A33: H-24 | B33: Make-up water supplied through an approved air gap or backflow prevention — no direct connection | C33: Shared — AB / Owner's Vendor | D33: AB plumbing scope — make-up water connection and backflow device | E33: DEP backflow certification + DOH acceptance | I33: Subpart 6-1 / NYC PC
A34: H-25 | B34: Pool equipment room floor drainage, sump and pump-out provided; room does not flood | C34: Shared — AB / Owner's Vendor | D34: AB slab, waterproofing, drainage and sump in AB scope | E34: As-built plumbing + flood test record | I34: Subpart 6-1
A35: H-26 | B35: Piping labelled and valve chart posted in the equipment room | C35: Shared — AB / Owner's Vendor | D35: AB labels AB-installed piping; vendor labels vendor piping | E35: Photo record + valve chart | I35: Best practice / Subpart 6-1
A36: H-27 | B36: Gutter / skimmer / overflow system provided per approved design | C36: Owner's Separate Trades | D36: AB interface at deck edge | E36: Approved design | I36: Subpart 6-1
A37: D. DISINFECTION, CHEMISTRY & CHEMICAL STORAGE
A38: H-28 | B38: Automated disinfectant feeder and pH control provided; capable of maintaining required residuals | C38: Owner's Separate Trades | D38: AB power and drainage to chemical controller location | E38: Equipment submittal | I38: Subpart 6-1
A39: H-29 | B39: Automated chemical controller with ORP / pH monitoring installed where required | C39: Owner's Separate Trades | D39: AB power and low-voltage rough-in | E39: Equipment submittal | I39: Subpart 6-1
A40: H-30 | B40: Chemical storage room / area separated, ventilated, with secondary containment and no incompatible storage | C40: Shared — AB / Owner's Vendor | D40: AB constructs and ventilates the chemical storage area — MEP and finishes in AB scope | E40: Approved layout + ventilation calc | I40: Subpart 6-1 / FDNY / NYC MC
A41: H-31 | B41: Eyewash / emergency shower provided at the chemical storage area if required | C41: Shared — AB / Owner's Vendor | D41: AB plumbing scope if required | E41: Approved plumbing plan | I41: OSHA / Subpart 6-1 — VERIFY
A42: H-32 | B42: Test kit(s) appropriate to the disinfectant in use provided on site | C42: Owner's Separate Trades | D42: None | E42: Purchase record | I42: Subpart 6-1
...

Sheet Statutory Inspections
A1: SAUNALOUNGE — STATUTORY INSPECTION & AGENCY APPROVAL LOG (DOB · FDNY · DOH · DEP · UTILITIES)
A2: Superintendent coordinates all inspections 48–72 hours in advance and records results immediately upon completion. Every inspector must sign the physical site log (see Inspector Sign-In tab). Final signed reports are compiled into the closeout package for TCO/CO issuance. (CMP §12.4, §12.6)
A4: Total | B4: =COUNTA($A$7:$A$60) -> 24 | C4: Passed | D4: =COUNTIF($I$7:$I$60,"Pass") -> 0 | E4: Failed / Re-inspect | F4: =COUNTIF($I$7:$I$60,"Fail")+COUNTIF($I$7:$I$60,"Re-inspect") -> 0 | G4: Outstanding | H4: =$B$4-COUNTIF($M$7:$M$60,"Closed") -> 24 | I4: Certificates Received | K4: =COUNTA($K$7:$K$60) -> 0
A6: ID | B6: Inspection / Approval | C6: Agency | D6: Discipline | E6: DOB NOW / Filing Ref | F6: Requested Date | G6: Scheduled Date | H6: Inspector Name | I6: Result | J6: Re-Insp. Date | K6: Certificate / Document Received | L6: Date Closed | M6: Status | N6: Linked TCO Gate | O6: Notes
A7: S-01 | B7: PW1 / PW2 permit issuance | C7: NYC DOB | D7: Permit | M7: Open | N7: A1
A8: S-02 | B8: Electrical rough inspection | C8: DOB Electrical | D8: Electrical | M8: Open | N8: D1
A9: S-03 | B9: Electrical final inspection / Certificate of Electrical Inspection | C9: DOB Electrical | D9: Electrical | M9: Open | N9: D2
A10: S-04 | B10: Con Edison energisation / energisation letter | C10: Con Edison | D10: Electrical | M10: Open | N10: D3
A11: S-05 | B11: Plumbing rough inspection — water / sanitary / vent | C11: DOB Plumbing | D11: Plumbing | M11: Open | N11: D4
A12: S-06 | B12: Gas pressure test witness — 10 psi / 15 min | C12: DOB Plumbing | D12: Gas | M12: Open | N12: D5
A13: S-07 | B13: Gas Activation Notice | C13: Con Edison / National Grid | D13: Gas | M13: Open | N13: D6
A14: S-08 | B14: DOB Boiler Unit inspection — Rheem water heaters | C14: DOB Boiler Unit | D14: Plumbing | M14: Open | N14: D7
A15: S-09 | B15: Plumbing final inspection / sign-off | C15: DOB Plumbing | D15: Plumbing | M15: Open | N15: D8
A16: S-10 | B16: DEP water meter set | C16: NYC DEP | D16: Water | M16: Open | N16: D9
A17: S-11 | B17: DEP backflow prevention device certification | C17: NYC DEP | D17: Water | M17: Open | N17: D10
A18: S-12 | B18: DEP final sewer connection approval | C18: NYC DEP | D18: Sewer | M18: Open | N18: D11
... A30: S-24 | B30: OSHA inspection (unannounced) | C30: OSHA | D30: Site Safety | M30: Open | N30: —

Sheet Special Inspections
A1: SAUNALOUNGE — SPECIAL INSPECTIONS LOG (NYC BC CHAPTER 17 · TR1 / TR2 / TR3 / TR8)
A2: Special Inspections for Tier 3 / Tier 4 DFOWs are MANDATORY HOLD POINTS — work may not advance until the report is received and uploaded to Procore. Notify the agency min. 48 hrs in advance. Every inspector must sign the physical site log. Final TR1 sign-off letter is a mandatory TCO prerequisite. (Playbook A6 / CMP §12.6)
A4: Total Events | B4: =COUNTA($A$7:$A$80) -> 36 | C4: Passed | D4: =COUNTIF($L$7:$L$80,"Pass") -> 0 | E4: Failed | F4: =COUNTIF($L$7:$L$80,"Fail") -> 0 | G4: Reports Outstanding | I4: =$B$4-COUNTA($M$7:$M$80) -> 36 | J4: Sign-In Verified | L4: =COUNTIF($K$7:$K$80,"Yes") -> 0
A6: ID | B6: Special Inspection Type | C6: Category / TR Ref | D6: Agency / Inspector Firm | E6: Frequency / Trigger | F6: DFOW Ref | G6: Location / Zone | H6: Notice Given | I6: Inspection Date | J6: Inspector Name | K6: Sign-In Log Verified | L6: Result | M6: Report Received | N6: Procore Ref | O6: NCR Raised | P6: Status | Q6: Notes
A7: SI-01 | B7: Concrete placement — pool equipment room slab | C7: TR2 / TR3 | D7: Licensed Testing Laboratory | E7: Each pour | F7: D-07 | G7: Pool equipment room | P7: Open
A8: SI-02 | B8: Concrete pre-pour rebar, embeds & formwork verification | C8: TR3 | D8: CodeGreen Inspection (CGI) | E8: Before every pour | F8: D-07 | G8: Pool equipment room | P8: Open | Q8: CGI: allow min. 2-3 days to schedule site visit
A9: SI-03 | B9: Concrete compressive strength testing (cylinder breaks) | C9: TR2 | D9: Licensed Testing Laboratory | E9: 1 set per 50 CY min. | F9: D-07 | G9: Pool equipment room | P9: Open
A10: SI-04 | B10: Excavation / support of excavation verification | C10: TR4 / TR5 | D10: CodeGreen Inspection (CGI) | E10: Before and during excavation | F10: D-08 | G10: Pool equipment room | P10: Open | Q10: CGI Structural Stability — 2 budgeted visits
A11: SI-05 | B11: Subgrade / soil bearing verification | C11: TR4 | D11: CodeGreen Inspection (CGI) | E11: Before slab placement | F11: D-08 | G11: Pool equipment room | P11: Open | Q11: CGI Structural Stability — 2 budgeted visits
A12: SI-06 | B12: Waterproofing — wet-area interface (locker rooms, showers, pool deck) | C12: TR12/13-adjacent | D12: Independent Inspector | E12: Prior to backfill / cover-up | F12: D-01 | G12: Zones A & B wet areas | P12: Open
A13: SI-07 | B13: Waterproofing interface at Owner's pool shell / sauna / cold plunge | C13: TR12/13-adjacent | D13: Independent Inspector | E13: Prior to cover-up, each interface | F13: D-02 | G13: Pool room (Zone B) | P13: Open
A14: SI-08 | B14: Firestopping of rated penetrations | C14: Ch.17 Firestop | D14: CodeGreen Inspection (CGI) | E14: Each rated penetration, before cover | F14: D-15 | G14: Whole premises | P14: Open | Q14: CGI Fire Stopping — inspector must witness installation
A15: SI-09 | B15: Mechanical systems / energy code compliance | C15: TR8 | D15: CodeGreen Inspection (CGI) | E15: At system completion | F15: D-10, D-11 | G15: Roof / Zones A & B | P15: Open | Q15: CGI Energy Code (EC) progress inspection — 3 budgeted visits
A16: SI-10 | B16: Duct leakage / pressure testing witness | C16: TR8 | D16: CodeGreen Inspection (CGI) / Collectif | E16: Each system before close-up | F16: D-11 | G16: Zones A & B | P16: Open | Q16: CGI MH Systems — 3 budgeted visits; approved HVAC balance report + equipment submittals required prior to sign-off
A17: SI-11 | B17: Mechanical ventilation / exhaust verification | C17: TR8 | D17: CodeGreen Inspection (CGI) / Collectif | E17: At system completion | F17: D-10 | G17: Zones A & B | P17: Open | Q17: CGI MH Systems — prior to installation of ceilings or other finishes
A18: SI-12 | B18: Energy code — insulation, air sealing & lighting controls | C18: TR8 | D18: CodeGreen Inspection (CGI) | E18: Progressive, before cover-up | F18: D-24 | G18: Whole premises | P18: Open | Q18: CGI Energy Code (EC) progress inspection
A19: SI-13 | B19: Sprinkler system — hydrostatic and flow testing | C19: TR1 / FDNY | D19: CodeGreen Inspection (CGI) | E19: Final acceptance | F19: D-04 | G19: Whole premises | P19: Open | Q19: CGI SP Systems hydro test — 1 budgeted visit; prior to connection of new system to building main
A20: SI-14 | B20: Fire alarm system — 100% device acceptance test | C20: TR1 / FDNY | D20: Approved Inspector | E20: Final acceptance | F20: D-03 | G20: Whole premises | P20: Open
A21: SI-15 | B21: Fire-resistance rated construction / penetrations verification | C21: Ch.17 | D21: CodeGreen Inspection (CGI) | E21: Progressive, before cover-up | F21: D-15, D-20 | G21: Whole premises | P21: Open | Q21: CGI Fire Stopping / Fire Proofing
A22: SI-16 | B22: Structural steel / miscellaneous metals connections (if in scope) | C22: TR1 | D22: CodeGreen Inspection (CGI) | E22: Each connection type | F22: D-18 | G22: Zones A & B | P22: Open
A23: SI-17 | B23: Post-installed anchors in concrete / masonry | C23: TR1 | D23: CodeGreen Inspection (CGI) | E23: Per approved frequency | F23: D-07 | G23: Zones A & B | P23: Open | Q23: CGI Post Installed Anchors — 1 budgeted visit; installers must be NYC DOB certified; inspector witnesses ALL phases
A24: SI-18 | B24: DOH Pool / Spa inspection (Owner's Separate Trades) | C24: DOH | D24: NYC DOH Inspector | E24: Prior to occupancy of pool / sauna areas | F24: — | G24: Pool room (Zone B) | P24: Open
